Workbook

Sheet Summary (2)
A1: GBP | J1: USD
A3: Customer | B3: Maintenance | C3: PS | D3: Def Licenses | E3: Perpetual Licenses | G3: Total Revenue 2024 (£) | J3: Maintenance | K3: PS | L3: Def Licenses | M3: Perpetual Licenses | O3: Total Revenue 2024 ($) | R3: COGS | T3: Net
A4: Frontier Agriculture | B4: =IFERROR(VLOOKUP(A4,'Annual Maintenance'!$A$1:$G$41,7,FALSE),0)+(21531*12) -> 1916081.5 | C4: =IFERROR(VLOOKUP(A4,#REF!,14,FALSE),0) -> 0 | D4: =IFERROR(VLOOKUP(A4,#REF!,14,FALSE),0) -> 0 | E4: =IFERROR(VLOOKUP(A4,'IFRS15 Licenses'!$U$12:$AH$28,14,FALSE),0) -> 0 | G4: =SUM(B4:F4) -> 1916081.5 | H4: =G4/$G$46 -> 0.3629409 | J4: =IFERROR(VLOOKUP(A4,'Annual Maintenance'!$A$1:$N$41,14,FALSE),0) -> 2189263.4 | K4: =IFERROR(VLOOKUP(A4,#REF!,14,FALSE),0) -> 0 | L4: =IFERROR(VLOOKUP(A4,#REF!,14,FALSE),0) -> 0 | M4: =IFERROR(VLOOKUP(A4,'IFRS15 Licenses'!#REF!,14,FALSE),0) -> 0 | O4: =SUM(J4:N4) -> 2189263.4 | R4: =IFERROR(VLOOKUP(A4,#REF!,14,FALSE),0) -> 0 | T4: =O4+R4 -> 2189263.4
A5: Openfield | B5: =IFERROR(VLOOKUP(A5,'Annual Maintenance'!$A$1:$G$41,7,FALSE),0) -> 829534.83 | C5: =IFERROR(VLOOKUP(A5,#REF!,14,FALSE),0) -> 0 | D5: =IFERROR(VLOOKUP(A5,#REF!,14,FALSE),0) -> 0 | E5: =IFERROR(VLOOKUP(A5,'IFRS15 Licenses'!$U$12:$AH$28,14,FALSE),0) -> 0 | G5: =SUM(B5:F5) -> 829534.83 | H5: =G5/$G$46 -> 0.15712908 | J5: =IFERROR(VLOOKUP(A5,'Annual Maintenance'!$A$1:$N$41,14,FALSE),0) -> 1095797.5 | K5: =IFERROR(VLOOKUP(A5,#REF!,14,FALSE),0) -> 0 | L5: =IFERROR(VLOOKUP(A5,#REF!,14,FALSE),0) -> 0 | M5: =IFERROR(VLOOKUP(A5,'IFRS15 Licenses'!#REF!,14,FALSE),0) -> 0 | O5: =SUM(J5:N5) -> 1095797.5 | R5: =IFERROR(VLOOKUP(A5,#REF!,14,FALSE),0) -> 0 | T5: =O5+R5 -> 1095797.5
A6: West Gaines Seeds | B6: =IFERROR(VLOOKUP(A6,'Annual Maintenance'!$A$1:$G$41,7,FALSE),0) -> 469478.42 | C6: =IFERROR(VLOOKUP(A6,#REF!,14,FALSE),0) -> 0 | D6: =IFERROR(VLOOKUP(A6,#REF!,14,FALSE),0) -> 0 | E6: =IFERROR(VLOOKUP(A6,'IFRS15 Licenses'!$U$12:$AH$28,14,FALSE),0) -> 8232.63 | G6: =SUM(B6:F6) -> 477711.05 | H6: =G6/$G$46 -> 0.090487214 | J6: =IFERROR(VLOOKUP(A6,'Annual Maintenance'!$A$1:$N$41,14,FALSE),0) -> 619973.78 | K6: =IFERROR(VLOOKUP(A6,#REF!,14,FALSE),0) -> 0 | L6: =IFERROR(VLOOKUP(A6,#REF!,14,FALSE),0) -> 0 | M6: =IFERROR(VLOOKUP(A6,'IFRS15 Licenses'!#REF!,14,FALSE),0) -> 0 | O6: =SUM(J6:N6) -> 619973.78 | R6: =IFERROR(VLOOKUP(A6,#REF!,14,FALSE),0) -> 0 | T6: =O6+R6 -> 619973.78
A7: Simpsons Malt | B7: =IFERROR(VLOOKUP(A7,'Annual Maintenance'!$A$1:$G$41,7,FALSE),0) -> 319982.68 | C7: =IFERROR(VLOOKUP(A7,#REF!,14,FALSE),0) -> 0 | D7: =IFERROR(VLOOKUP(A7,#REF!,14,FALSE),0) -> 0 | E7: =IFERROR(VLOOKUP(A7,'IFRS15 Licenses'!$U$12:$AH$28,14,FALSE),0) -> 22700.004 | G7: =SUM(B7:F7) -> 342682.68 | H7: =G7/$G$46 -> 0.06491037 | J7: =IFERROR(VLOOKUP(A7,'Annual Maintenance'!$A$1:$N$41,14,FALSE),0) -> 422658.16 | K7: =IFERROR(VLOOKUP(A7,#REF!,14,FALSE),0) -> 0 | L7: =IFERROR(VLOOKUP(A7,#REF!,14,FALSE),0) -> 0 | M7: =IFERROR(VLOOKUP(A7,'IFRS15 Licenses'!#REF!,14,FALSE),0) -> 0 | O7: =SUM(J7:N7) -> 422658.16 | R7: =IFERROR(VLOOKUP(A7,#REF!,14,FALSE),0) -> 0 | T7: =O7+R7 -> 422658.16
A8: Wynnstay Group | B8: =IFERROR(VLOOKUP(A8,'Annual Maintenance'!$A$1:$G$41,7,FALSE),0) -> 168704.17 | C8: =IFERROR(VLOOKUP(A8,#REF!,14,FALSE),0) -> 0 | D8: =IFERROR(VLOOKUP(A8,#REF!,14,FALSE),0) -> 0 | E8: =IFERROR(VLOOKUP(A8,'IFRS15 Licenses'!$U$12:$AH$28,14,FALSE),0) -> 307.3 | G8: =SUM(B8:F8) -> 169011.47 | H8: =G8/$G$46 -> 0.032013865 | J8: =IFERROR(VLOOKUP(A8,'Annual Maintenance'!$A$1:$N$41,14,FALSE),0) -> 222784.75 | K8: =IFERROR(VLOOKUP(A8,#REF!,14,FALSE),0) -> 0 | L8: =IFERROR(VLOOKUP(A8,#REF!,14,FALSE),0) -> 0 | M8: =IFERROR(VLOOKUP(A8,'IFRS15 Licenses'!#REF!,14,FALSE),0) -> 0 | O8: =SUM(J8:N8) -> 222784.75 | R8: =IFERROR(VLOOKUP(A8,#REF!,14,FALSE),0) -> 0 | T8: =O8+R8 -> 222784.75
A9: Oxbow Coal | B9: =IFERROR(VLOOKUP(A9,'Annual Maintenance'!$A$1:$G$41,7,FALSE),0) -> 191809.9 | C9: =IFERROR(VLOOKUP(A9,#REF!,14,FALSE),0) -> 0 | D9: =IFERROR(VLOOKUP(A9,#REF!,14,FALSE),0) -> 0 | E9: =IFERROR(VLOOKUP(A9,'IFRS15 Licenses'!$U$12:$AH$28,14,FALSE),0) -> 0 | G9: =SUM(B9:F9) -> 191809.9 | H9: =G9/$G$46 -> 0.036332304 | J9: =IFERROR(VLOOKUP(A9,'Annual Maintenance'!$A$1:$N$41,14,FALSE),0) -> 253302.62 | K9: =IFERROR(VLOOKUP(A9,#REF!,14,FALSE),0) -> 0 | L9: =IFERROR(VLOOKUP(A9,#REF!,14,FALSE),0) -> 0 | M9: =IFERROR(VLOOKUP(A9,'IFRS15 Licenses'!#REF!,14,FALSE),0) -> 0 | O9: =SUM(J9:N9) -> 253302.62 | R9: =IFERROR(VLOOKUP(A9,#REF!,14,FALSE),0) -> 0 | T9: =O9+R9 -> 253302.62
A10: Saxon Agriculture | B10: =IFERROR(VLOOKUP(A10,'Annual Maintenance'!$A$1:$G$41,7,FALSE),0) -> 133642.21 | C10: =IFERROR(VLOOKUP(A10,#REF!,14,FALSE),0) -> 0 | D10: =IFERROR(VLOOKUP(A10,#REF!,14,FALSE),0) -> 0 | E10: =IFERROR(VLOOKUP(A10,'IFRS15 Licenses'!$U$12:$AH$28,14,FALSE),0) -> 11917 | G10: =SUM(B10:F10) -> 145559.21 | H10: =G10/$G$46 -> 0.027571577 | J10: =IFERROR(VLOOKUP(A10,'Annual Maintenance'!$A$1:$N$41,14,FALSE),0) -> 176676.87 | K10: =IFERROR(VLOOKUP(A10,#REF!,14,FALSE),0) -> 0 | L10: =IFERROR(VLOOKUP(A10,#REF!,14,FALSE),0) -> 0 | M10: =IFERROR(VLOOKUP(A10,'IFRS15 Licenses'!#REF!,14,FALSE),0) -> 0 | O10: =SUM(J10:N10) -> 176676.87 | R10: =IFERROR(VLOOKUP(A10,#REF!,14,FALSE),0) -> 0 | T10: =O10+R10 -> 176676.87
A11: Denholm Fish Selling Ltd | B11: =IFERROR(VLOOKUP(A11,'Annual Maintenance'!$A$1:$G$41,7,FALSE),0) -> 55553.323 | C11: =IFERROR(VLOOKUP(A11,#REF!,14,FALSE),0) -> 0 | D11: =IFERROR(VLOOKUP(A11,#REF!,14,FALSE),0) -> 0 | E11: =IFERROR(VLOOKUP(A11,'IFRS15 Licenses'!$U$12:$AH$28,14,FALSE),0) -> 0 | G11: =SUM(B11:F11) -> 55553.323 | H11: =G11/$G$46 -> 0.010522816 | J11: =IFERROR(VLOOKUP(A11,'Annual Maintenance'!$A$1:$N$41,14,FALSE),0) -> 73384.077 | K11: =IFERROR(VLOOKUP(A11,#REF!,14,FALSE),0) -> 0 | L11: =IFERROR(VLOOKUP(A11,#REF!,14,FALSE),0) -> 0 | M11: =IFERROR(VLOOKUP(A11,'IFRS15 Licenses'!#REF!,14,FALSE),0) -> 0 | O11: =SUM(J11:N11) -> 73384.077 | R11: =IFERROR(VLOOKUP(A11,#REF!,14,FALSE),0) -> 0 | T11: =O11+R11 -> 73384.077
A12: Grainco | B12: =IFERROR(VLOOKUP(A12,'Annual Maintenance'!$A$1:$G$41,7,FALSE),0) -> 94530.098 | C12: =IFERROR(VLOOKUP(A12,#REF!,14,FALSE),0) -> 0 | D12: =IFERROR(VLOOKUP(A12,#REF!,14,FALSE),0) -> 0 | E12: =IFERROR(VLOOKUP(A12,'IFRS15 Licenses'!$U$12:$AH$28,14,FALSE),0) -> 0 | G12: =SUM(B12:F12) -> 94530.098 | H12: =G12/$G$46 -> 0.01790573 | J12: =IFERROR(VLOOKUP(A12,'Annual Maintenance'!$A$1:$N$41,14,FALSE),0) -> 124842.02 | K12: =IFERROR(VLOOKUP(A12,#REF!,14,FALSE),0) -> 0 | L12: =IFERROR(VLOOKUP(A12,#REF!,14,FALSE),0) -> 0 | M12: =IFERROR(VLOOKUP(A12,'IFRS15 Licenses'!#REF!,14,FALSE),0) -> 0 | O12: =SUM(J12:N12) -> 124842.02 | R12: =IFERROR(VLOOKUP(A12,#REF!,14,FALSE),0) -> 0 | T12: =O12+R12 -> 124842.02
A13: AB Agri | B13: =IFERROR(VLOOKUP(A13,'Annual Maintenance'!$A$1:$G$41,7,FALSE),0) -> 86882.937 | C13: =IFERROR(VLOOKUP(A13,#REF!,14,FALSE),0) -> 0 | D13: =IFERROR(VLOOKUP(A13,#REF!,14,FALSE),0) -> 0 | E13: =IFERROR(VLOOKUP(A13,'IFRS15 Licenses'!$U$12:$AH$28,14,FALSE),0) -> 0 | F13: =IFERROR(VLOOKUP(#REF!,'IFRS15 Licenses'!$U$12:$AH$25,14,FALSE),0) -> 0 | G13: =SUM(B13:F13) -> 86882.937 | H13: =G13/$G$46 -> 0.016457218 | J13: =IFERROR(VLOOKUP(A13,'Annual Maintenance'!$A$1:$N$41,14,FALSE),0) -> 114783.73 | K13: =IFERROR(VLOOKUP(A13,#REF!,14,FALSE),0) -> 0 | L13: =IFERROR(VLOOKUP(A13,#REF!,14,FALSE),0) -> 0 | M13: =IFERROR(VLOOKUP(A13,'IFRS15 Licenses'!#REF!,14,FALSE),0) -> 0 | O13: =SUM(J13:N13) -> 114783.73 | R13: =IFERROR(VLOOKUP(A13,#REF!,14,FALSE),0) -> 0 | T13: =O13+R13 -> 114783.73
A14: Glasson Grain | B14: =IFERROR(VLOOKUP(A14,'Annual Maintenance'!$A$1:$G$41,7,FALSE),0) -> 98202.427 | C14: =IFERROR(VLOOKUP(A14,#REF!,14,FALSE),0) -> 0 | D14: =IFERROR(VLOOKUP(A14,#REF!,14,FALSE),0) -> 0 | E14: =IFERROR(VLOOKUP(A14,'IFRS15 Licenses'!$U$12:$AH$28,14,FALSE),0) -> 350 | G14: =SUM(B14:F14) -> 98552.427 | H14: =G14/$G$46 -> 0.018667633 | J14: =IFERROR(VLOOKUP(A14,'Annual Maintenance'!$A$1:$N$41,14,FALSE),0) -> 129721.69 | K14: =IFERROR(VLOOKUP(A14,#REF!,14,FALSE),0) -> 0 | L14: =IFERROR(VLOOKUP(A14,#REF!,14,FALSE),0) -> 0 | M14: =IFERROR(VLOOKUP(A14,'IFRS15 Licenses'!#REF!,14,FALSE),0) -> 0 | O14: =SUM(J14:N14) -> 129721.69 | R14: =IFERROR(VLOOKUP(A14,#REF!,14,FALSE),0) -> 0 | T14: =O14+R14 -> 129721.69
A15: Canterra Seeds | B15: =IFERROR(VLOOKUP(A15,'Annual Maintenance'!$A$1:$G$41,7,FALSE),0) -> 62095.212 | C15: =IFERROR(VLOOKUP(A15,#REF!,14,FALSE),0) -> 0 | D15: =IFERROR(VLOOKUP(A15,#REF!,14,FALSE),0) -> 0 | E15: =IFERROR(VLOOKUP(A15,'IFRS15 Licenses'!$U$12:$AH$28,14,FALSE),0) -> 5751.166 | G15: =SUM(B15:F15) -> 67846.378 | H15: =G15/$G$46 -> 0.012851345 | J15: =IFERROR(VLOOKUP(A15,'Annual Maintenance'!$A$1:$N$41,14,FALSE),0) -> 82024.538 | K15: =IFERROR(VLOOKUP(A15,#REF!,14,FALSE),0) -> 0 | L15: =IFERROR(VLOOKUP(A15,#REF!,14,FALSE),0) -> 0 | M15: =IFERROR(VLOOKUP(A15,'IFRS15 Licenses'!#REF!,14,FALSE),0) -> 0 | O15: =SUM(J15:N15) -> 82024.538 | R15: =IFERROR(VLOOKUP(A15,#REF!,14,FALSE),0) -> 0 | T15: =O15+R15 -> 82024.538
A16: Harlow Agriculture | B16: =IFERROR(VLOOKUP(A16,'Annual Maintenance'!$A$1:$G$41,7,FALSE),0) -> 92092.844 | C16: =IFERROR(VLOOKUP(A16,#REF!,14,FALSE),0) -> 0 | D16: =IFERROR(VLOOKUP(A16,#REF!,14,FALSE),0) -> 0 | E16: =IFERROR(VLOOKUP(A16,'IFRS15 Licenses'!$U$12:$AH$28,14,FALSE),0) -> 522.2 | G16: =SUM(B16:F16) -> 92615.044 | H16: =G16/$G$46 -> 0.017542984 | J16: =IFERROR(VLOOKUP(A16,'Annual Maintenance'!$A$1:$N$41,14,FALSE),0) -> 121654.52 | K16: =IFERROR(VLOOKUP(A16,#REF!,14,FALSE),0) -> 0 | L16: =IFERROR(VLOOKUP(A16,#REF!,14,FALSE),0) -> 0 | M16: =IFERROR(VLOOKUP(A16,'IFRS15 Licenses'!#REF!,14,FALSE),0) -> 0 | O16: =SUM(J16:N16) -> 121654.52 | R16: =IFERROR(VLOOKUP(A16,#REF!,14,FALSE),0) -> 0 | T16: =O16+R16 -> 121654.52
A17: H J Lea | B17: =IFERROR(VLOOKUP(A17,'Annual Maintenance'!$A$1:$G$41,7,FALSE),0) -> 82017.101 | C17: =IFERROR(VLOOKUP(A17,#REF!,14,FALSE),0) -> 0 | D17: =IFERROR(VLOOKUP(A17,#REF!,14,FALSE),0) -> 0 | E17: =IFERROR(VLOOKUP(A17,'IFRS15 Licenses'!$U$12:$AH$28,14,FALSE),0) -> 1000 | G17: =SUM(B17:F17) -> 83017.101 | H17: =G17/$G$46 -> 0.015724958 | J17: =IFERROR(VLOOKUP(A17,'Annual Maintenance'!$A$1:$N$41,14,FALSE),0) -> 108214.26 | K17: =IFERROR(VLOOKUP(A17,#REF!,14,FALSE),0) -> 0 | L17: =IFERROR(VLOOKUP(A17,#REF!,14,FALSE),0) -> 0 | M17: =IFERROR(VLOOKUP(A17,'IFRS15 Licenses'!#REF!,14,FALSE),0) -> 0 | O17: =SUM(J17:N17) -> 108214.26 | R17: =IFERROR(VLOOKUP(A17,#REF!,14,FALSE),0) -> 0 | T17: =O17+R17 -> 108214.26
A18: WCF | B18: =IFERROR(VLOOKUP(A18,'Annual Maintenance'!$A$1:$G$41,7,FALSE),0) -> 73052.513 | C18: =IFERROR(VLOOKUP(A18,#REF!,14,FALSE),0) -> 0 | D18: =IFERROR(VLOOKUP(A18,#REF!,14,FALSE),0) -> 0 | E18: =IFERROR(VLOOKUP(A18,'IFRS15 Licenses'!$U$12:$AH$28,14,FALSE),0) -> 0 | G18: =SUM(B18:F18) -> 73052.513 | H18: =G18/$G$46 -> 0.013837483 | J18: =IFERROR(VLOOKUP(A18,'Annual Maintenance'!$A$1:$N$41,14,FALSE),0) -> 96486.212 | K18: =IFERROR(VLOOKUP(A18,#REF!,14,FALSE),0) -> 0 | L18: =IFERROR(VLOOKUP(A18,#REF!,14,FALSE),0) -> 0 | M18: =IFERROR(VLOOKUP(A18,'IFRS15 Licenses'!#REF!,14,FALSE),0) -> 0 | O18: =SUM(J18:N18) -> 96486.212 | R18: =IFERROR(VLOOKUP(A18,#REF!,14,FALSE),0) -> 0 | T18: =O18+R18 -> 96486.212
A19: Fram Farmers | B19: =IFERROR(VLOOKUP(A19,'Annual Maintenance'!$A$1:$G$41,7,FALSE),0) -> 29460.291 | C19: =IFERROR(VLOOKUP(A19,#REF!,14,FALSE),0) -> 0 | D19: =IFERROR(VLOOKUP(A19,#REF!,14,FALSE),0) -> 0 | E19: =IFERROR(VLOOKUP(A19,'IFRS15 Licenses'!$U$12:$AH$28,14,FALSE),0) -> 8139 | G19: =SUM(B19:F19) -> 37599.291 | H19: =G19/$G$46 -> 0.0071219937 | J19: =IFERROR(VLOOKUP(A19,'Annual Maintenance'!$A$1:$N$41,14,FALSE),0) -> 38924.124 | K19: =IFERROR(VLOOKUP(A19,#REF!,14,FALSE),0) -> 0 | L19: =IFERROR(VLOOKUP(A19,#REF!,14,FALSE),0) -> 0 | M19: =IFERROR(VLOOKUP(A19,'IFRS15 Licenses'!#REF!,14,FALSE),0) -> 0 | O19: =SUM(J19:N19) -> 38924.124 | R19: =IFERROR(VLOOKUP(A19,#REF!,14,FALSE),0) -> 0 | T19: =O19+R19 -> 38924.124
A20: Barenbrug | B20: =IFERROR(VLOOKUP(A20,'Annual Maintenance'!$A$1:$G$41,7,FALSE),0) -> 59091.87 | C20: =IFERROR(VLOOKUP(A20,#REF!,14,FALSE),0) -> 0 | D20: =IFERROR(VLOOKUP(A20,#REF!,14,FALSE),0) -> 0 | E20: =IFERROR(VLOOKUP(A20,'IFRS15 Licenses'!$U$12:$AH$28,14,FALSE),0) -> 3153.2 | G20: =SUM(B20:F20) -> 62245.07 | H20: =G20/$G$46 -> 0.011790355 | J20: =IFERROR(VLOOKUP(A20,'Annual Maintenance'!$A$1:$N$41,14,FALSE),0) -> 78042.149 | K20: =IFERROR(VLOOKUP(A20,#REF!,14,FALSE),0) -> 0 | L20: =IFERROR(VLOOKUP(A20,#REF!,14,FALSE),0) -> 0 | M20: =IFERROR(VLOOKUP(A20,'IFRS15 Licenses'!#REF!,14,FALSE),0) -> 0 | O20: =SUM(J20:N20) -> 78042.149 | R20: =IFERROR(VLOOKUP(A20,#REF!,14,FALSE),0) -> 0 | T20: =O20+R20 -> 78042.149
A21: Dugdale Nutrition | B21: =IFERROR(VLOOKUP(A21,'Annual Maintenance'!$A$1:$G$41,7,FALSE),0) -> 64354.47 | C21: =IFERROR(VLOOKUP(A21,#REF!,14,FALSE),0) -> 0 | D21: =IFERROR(VLOOKUP(A21,#REF!,14,FALSE),0) -> 0 | E21: =IFERROR(VLOOKUP(A21,'IFRS15 Licenses'!$U$12:$AH$28,14,FALSE),0) -> 450 | G21: =SUM(B21:F21) -> 64804.47 | H21: =G21/$G$46 -> 0.012275152 | J21: =IFERROR(VLOOKUP(A21,'Annual Maintenance'!$A$1:$N$41,14,FALSE),0) -> 85005.466 | K21: =IFERROR(VLOOKUP(A21,#REF!,14,FALSE),0) -> 0 | L21: =IFERROR(VLOOKUP(A21,#REF!,14,FALSE),0) -> 0 | M21: =IFERROR(VLOOKUP(A21,'IFRS15 Licenses'!#REF!,14,FALSE),0) -> 0 | O21: =SUM(J21:N21) -> 85005.466 | R21: =IFERROR(VLOOKUP(A21,#REF!,14,FALSE),0) -> 0 | T21: =O21+R21 -> 85005.466
A22: COFCO International | B22: =IFERROR(VLOOKUP(A22,'Annual Maintenance'!$A$1:$G$41,7,FALSE),0) -> 62529.616 | C22: =IFERROR(VLOOKUP(A22,#REF!,14,FALSE),0) -> 0 | D22: =IFERROR(VLOOKUP(A22,#REF!,14,FALSE),0) -> 0 | E22: =IFERROR(VLOOKUP(A22,'IFRS15 Licenses'!$U$12:$AH$28,14,FALSE),0) -> 0 | G22: =SUM(B22:F22) -> 62529.616 | H22: =G22/$G$46 -> 0.011844253 | J22: =IFERROR(VLOOKUP(A22,'Annual Maintenance'!$A$1:$N$41,14,FALSE),0) -> 82579.986 | K22: =IFERROR(VLOOKUP(A22,#REF!,14,FALSE),0) -> 0 | L22: =IFERROR(VLOOKUP(A22,#REF!,14,FALSE),0) -> 0 | M22: =IFERROR(VLOOKUP(A22,'IFRS15 Licenses'!#REF!,14,FALSE),0) -> 0 | O22: =SUM(J22:N22) -> 82579.986 | R22: =IFERROR(VLOOKUP(A22,#REF!,14,FALSE),0) -> 0 | T22: =O22+R22 -> 82579.986
A23: Robin Appel | B23: =IFERROR(VLOOKUP(A23,'Annual Maintenance'!$A$1:$G$41,7,FALSE),0) -> 49718.13 | C23: =IFERROR(VLOOKUP(A23,#REF!,14,FALSE),0) -> 0 | D23: =IFERROR(VLOOKUP(A23,#REF!,14,FALSE),0) -> 0 | E23: =IFERROR(VLOOKUP(A23,'IFRS15 Licenses'!$U$12:$AH$28,14,FALSE),0) -> 0 | G23: =SUM(B23:F23) -> 49718.13 | H23: =G23/$G$46 -> 0.0094175235 | J23: =IFERROR(VLOOKUP(A23,'Annual Maintenance'!$A$1:$N$41,14,FALSE),0) -> 65674.384 | K23: =IFERROR(VLOOKUP(A23,#REF!,14,FALSE),0) -> 0 | L23: =IFERROR(VLOOKUP(A23,#REF!,14,FALSE),0) -> 0 | M23: =IFERROR(VLOOKUP(A23,'IFRS15 Licenses'!#REF!,14,FALSE),0) -> 0 | O23: =SUM(J23:N23) -> 65674.384 | R23: =IFERROR(VLOOKUP(A23,#REF!,14,FALSE),0) -> 0 | T23: =O23+R23 -> 65674.384
A24: ADM Direct | B24: =IFERROR(VLOOKUP(A24,'Annual Maintenance'!$A$1:$G$41,7,FALSE),0) -> 24683.533 | C24: =IFERROR(VLOOKUP(A24,#REF!,14,FALSE),0) -> 0 | D24: =IFERROR(VLOOKUP(A24,#REF!,14,FALSE),0) -> 0 | E24: =IFERROR(VLOOKUP(A24,'IFRS15 Licenses'!$U$12:$AH$28,14,FALSE),0) -> 0 | G24: =SUM(B24:F24) -> 24683.533 | H24: =G24/$G$46 -> 0.0046755127 | J24: =IFERROR(VLOOKUP(A24,'Annual Maintenance'!$A$1:$N$41,14,FALSE),0) -> 32178.468 | K24: =IFERROR(VLOOKUP(A24,#REF!,14,FALSE),0) -> 0 | L24: =IFERROR(VLOOKUP(A24,#REF!,14,FALSE),0) -> 0 | M24: =IFERROR(VLOOKUP(A24,'IFRS15 Licenses'!#REF!,14,FALSE),0) -> 0 | O24: =SUM(J24:N24) -> 32178.468 | R24: =IFERROR(VLOOKUP(A24,#REF!,14,FALSE),0) -> 0 | T24: =O24+R24 -> 32178.468
A25: Banff & Moray Grain (Marketing) Ltd | B25: =IFERROR(VLOOKUP(A25,'Annual Maintenance'!$A$1:$G$41,7,FALSE),0) -> 13137.103 | C25: =IFERROR(VLOOKUP(A25,#REF!,14,FALSE),0) -> 0 | D25: =IFERROR(VLOOKUP(A25,#REF!,14,FALSE),0) -> 0 | E25: =IFERROR(VLOOKUP(A25,'IFRS15 Licenses'!$U$12:$AH$28,14,FALSE),0) -> 6510 | G25: =SUM(B25:F25) -> 19647.103 | H25: =G25/$G$46 -> 0.0037215208 | J25: =IFERROR(VLOOKUP(A25,'Annual Maintenance'!$A$1:$N$41,14,FALSE),0) -> 17352.92 | K25: =IFERROR(VLOOKUP(A25,#REF!,14,FALSE),0) -> 0 | L25: =IFERROR(VLOOKUP(A25,#REF!,14,FALSE),0) -> 0 | M25: =IFERROR(VLOOKUP(A25,'IFRS15 Licenses'!#REF!,14,FALSE),0) -> 0 | O25: =SUM(J25:N25) -> 17352.92 | R25: =IFERROR(VLOOKUP(A25,#REF!,14,FALSE),0) -> 0 | T25: =O25+R25 -> 17352.92
... A43: E B Bradshaws | B43: =IFERROR(VLOOKUP(A43,'Annual Maintenance'!$A$1:$G$41,7,FALSE),0) -> 0 | C43: =IFERROR(VLOOKUP(A43,#REF!,14,FALSE),0) -> 0 | D43: =IFERROR(VLOOKUP(A43,#REF!,14,FALSE),0) -> 0 | E43: =IFERROR(VLOOKUP(A43,'IFRS15 Licenses'!$U$12:$AH$28,14,FALSE),0) -> 0 | G43: =SUM(B43:F43) -> 0 | H43: =G43/$G$46 -> 0 | J43: =IFERROR(VLOOKUP(A43,'Annual Maintenance'!$A$1:$N$41,14,FALSE),0) -> 0 | K43: =IFERROR(VLOOKUP(A43,#REF!,14,FALSE),0) -> 0 | L43: =IFERROR(VLOOKUP(A43,#REF!,14,FALSE),0) -> 0 | M43: =IFERROR(VLOOKUP(A43,'IFRS15 Licenses'!#REF!,14,FALSE),0) -> 0 | O43: =SUM(J43:N43) -> 0 | R43: =IFERROR(VLOOKUP(A43,#REF!,14,FALSE),0) -> 0 | T43: =O43+R43 -> 0
A44: Humphrey Farms | B44: =IFERROR(VLOOKUP(A44,'Annual Maintenance'!$A$1:$G$41,7,FALSE),0) -> 0 | C44: =IFERROR(VLOOKUP(A44,#REF!,14,FALSE),0) -> 0 | D44: =IFERROR(VLOOKUP(A44,#REF!,14,FALSE),0) -> 0 | E44: =IFERROR(VLOOKUP(A44,'IFRS15 Licenses'!$U$12:$AH$28,14,FALSE),0) -> 0 | G44: =SUM(B44:F44) -> 0 | H44: =G44/$G$46 -> 0 | J44: =IFERROR(VLOOKUP(A44,'Annual Maintenance'!$A$1:$N$41,14,FALSE),0) -> 0 | K44: =IFERROR(VLOOKUP(A44,#REF!,14,FALSE),0) -> 0 | L44: =IFERROR(VLOOKUP(A44,#REF!,14,FALSE),0) -> 0 | M44: =IFERROR(VLOOKUP(A44,'IFRS15 Licenses'!#REF!,14,FALSE),0) -> 0 | O44: =SUM(J44:N44) -> 0
B46: =SUM(B4:B45) -> 5207788.5 | C46: =SUM(C4:C45) -> 0 | D46: =SUM(D4:D45) -> 0 | E46: =SUM(E4:E45) -> 71532.5 | F46: =SUM(F4:F45) -> 0 | G46: =SUM(G4:G45) -> 5279321 | J46: =SUM(J4:J45) -> 6536804.9 | K46: =SUM(K4:K45) -> 0 | L46: =SUM(L4:L45) -> 0 | M46: =SUM(M4:M45) -> 0 | N46: =SUM(N4:N45) -> 0 | O46: =SUM(O4:O45) -> 6536804.9 | P46: =SUM(P4:P45) -> 0 | Q46: =SUM(Q4:Q45) -> 0 | ... T46: =SUM(T4:T45) -> 6536804.9

Sheet Summary
A1: GBP | J1: USD
A3: Customer | C3: Maintenance | D3: PS | E3: Def Licenses | F3: Perpetual Licenses | H3: Total Revenue 2025 Q3 (£) | J3: Maintenance | K3: PS | L3: Def Licenses | M3: Perpetual Licenses | O3: Total Revenue 2024 ($) | P3: COGS | R3: COGS License
A4: AB Agri | B4: UK | C4: =IFERROR(VLOOKUP(A4,'Annual Maintenance'!$A$1:$G$41,7,FALSE),0) -> 86882.937 | D4: =-IFERROR(VLOOKUP(A4,'PS Pivot'!$B$5:$O$39,14,FALSE),0) -> 0 | E4: =IFERROR(VLOOKUP(A4,Licenses!$A$4:$N$25,14,FALSE),0) -> 0 | F4: =IFERROR(VLOOKUP(A4,'IFRS15 Licenses'!$U$10:$AH$26,14,FALSE),0) -> 0 | G4: =IFERROR(VLOOKUP(B4,'IFRS15 Licenses'!$U$12:$AH$25,14,FALSE),0) -> 0 | H4: =SUM(C4:G4) -> 86882.937 | J4: =IFERROR(VLOOKUP(A4,'Annual Maintenance'!$A$1:$N$41,14,FALSE),0) -> 114783.73 | K4: =IFERROR(VLOOKUP(A4,'PS Pivot'!$B$35:$O$56,14,FALSE),0) -> 0 | L4: =IFERROR(VLOOKUP(A4,Licenses!$A$35:$N$53,14,FALSE),0) -> 0 | M4: =IFERROR(VLOOKUP(A4,'IFRS15 Licenses'!$U$37:$AH$51,14,FALSE),0) -> 0 | O4: =SUM(J4:N4) -> 114783.73 | P4: =IFERROR(VLOOKUP(A4,COGS!$A$204:$N$238,14,FALSE),0) -> 0 | R4: =IFERROR(VLOOKUP(A4,'COGS License'!$A$23:$N$34,14,FALSE),0) -> 0
A5: Adams & Howling | B5: UK | C5: =IFERROR(VLOOKUP(A5,'Annual Maintenance'!$A$1:$G$41,7,FALSE),0) -> 34651.316 | D5: =-IFERROR(VLOOKUP(A5,'PS Pivot'!$B$5:$O$39,14,FALSE),0) -> 2960 | E5: =IFERROR(VLOOKUP(A5,Licenses!$A$4:$N$25,14,FALSE),0) -> 0 | F5: =IFERROR(VLOOKUP(A5,'IFRS15 Licenses'!$U$10:$AH$26,14,FALSE),0) -> 0 | H5: =SUM(C5:G5) -> 37611.316 | J5: =IFERROR(VLOOKUP(A5,'Annual Maintenance'!$A$1:$N$41,14,FALSE),0) -> 45771.226 | K5: =IFERROR(VLOOKUP(A5,'PS Pivot'!$B$35:$O$56,14,FALSE),0) -> -3981.2772 | L5: =IFERROR(VLOOKUP(A5,Licenses!$A$35:$N$53,14,FALSE),0) -> 0 | M5: =IFERROR(VLOOKUP(A5,'IFRS15 Licenses'!$U$37:$AH$51,14,FALSE),0) -> 0 | O5: =SUM(J5:N5) -> 41789.949 | P5: =IFERROR(VLOOKUP(A5,COGS!$A$204:$N$238,14,FALSE),0) -> -2391.4921 | R5: =IFERROR(VLOOKUP(A5,'COGS License'!$A$23:$N$34,14,FALSE),0) -> 0
A6: ADM Direct | B6: UK | C6: =IFERROR(VLOOKUP(A6,'Annual Maintenance'!$A$1:$G$41,7,FALSE),0) -> 24683.533 | D6: =-IFERROR(VLOOKUP(A6,'PS Pivot'!$B$5:$O$39,14,FALSE),0) -> 0 | E6: =IFERROR(VLOOKUP(A6,Licenses!$A$4:$N$25,14,FALSE),0) -> 0 | F6: =IFERROR(VLOOKUP(A6,'IFRS15 Licenses'!$U$10:$AH$26,14,FALSE),0) -> 0 | H6: =SUM(C6:G6) -> 24683.533 | J6: =IFERROR(VLOOKUP(A6,'Annual Maintenance'!$A$1:$N$41,14,FALSE),0) -> 32178.468 | K6: =IFERROR(VLOOKUP(A6,'PS Pivot'!$B$35:$O$56,14,FALSE),0) -> 0 | L6: =IFERROR(VLOOKUP(A6,Licenses!$A$35:$N$53,14,FALSE),0) -> 0 | M6: =IFERROR(VLOOKUP(A6,'IFRS15 Licenses'!$U$37:$AH$51,14,FALSE),0) -> 0 | O6: =SUM(J6:N6) -> 32178.468 | P6: =IFERROR(VLOOKUP(A6,COGS!$A$204:$N$238,14,FALSE),0) -> 0 | R6: =IFERROR(VLOOKUP(A6,'COGS License'!$A$23:$N$34,14,FALSE),0) -> 0
A7: Banff & Moray Grain (Marketing) Ltd | B7: UK | C7: =IFERROR(VLOOKUP(A7,'Annual Maintenance'!$A$1:$G$41,7,FALSE),0) -> 13137.103 | D7: =-IFERROR(VLOOKUP(A7,'PS Pivot'!$B$5:$O$39,14,FALSE),0) -> 2619.6 | E7: =IFERROR(VLOOKUP(A7,Licenses!$A$4:$N$25,14,FALSE),0) -> 0 | F7: =IFERROR(VLOOKUP(A7,'IFRS15 Licenses'!$U$10:$AH$26,14,FALSE),0) -> 6510 | H7: =SUM(C7:G7) -> 22266.703 | J7: =IFERROR(VLOOKUP(A7,'Annual Maintenance'!$A$1:$N$41,14,FALSE),0) -> 17352.92 | K7: =IFERROR(VLOOKUP(A7,'PS Pivot'!$B$35:$O$56,14,FALSE),0) -> -3531.6928 | L7: =IFERROR(VLOOKUP(A7,Licenses!$A$35:$N$53,14,FALSE),0) -> 0 | M7: =IFERROR(VLOOKUP(A7,'IFRS15 Licenses'!$U$37:$AH$51,14,FALSE),0) -> 8725.0203 | O7: =SUM(J7:N7) -> 22546.247 | P7: =IFERROR(VLOOKUP(A7,COGS!$A$204:$N$238,14,FALSE),0) -> -1189.5022 | R7: =IFERROR(VLOOKUP(A7,'COGS License'!$A$23:$N$34,14,FALSE),0) -> 0
A8: Barenbrug | B8: UK | C8: =IFERROR(VLOOKUP(A8,'Annual Maintenance'!$A$1:$G$41,7,FALSE),0) -> 59091.87 | D8: =-IFERROR(VLOOKUP(A8,'PS Pivot'!$B$5:$O$39,14,FALSE),0) -> 0 | E8: =IFERROR(VLOOKUP(A8,Licenses!$A$4:$N$25,14,FALSE),0) -> 448.37 | F8: =IFERROR(VLOOKUP(A8,'IFRS15 Licenses'!$U$10:$AH$26,14,FALSE),0) -> 3153.2 | H8: =SUM(C8:G8) -> 62693.44 | J8: =IFERROR(VLOOKUP(A8,'Annual Maintenance'!$A$1:$N$41,14,FALSE),0) -> 78042.149 | K8: =IFERROR(VLOOKUP(A8,'PS Pivot'!$B$35:$O$56,14,FALSE),0) -> 0 | L8: =IFERROR(VLOOKUP(A8,Licenses!$A$35:$N$53,14,FALSE),0) -> 556.64254 | M8: =IFERROR(VLOOKUP(A8,'IFRS15 Licenses'!$U$37:$AH$51,14,FALSE),0) -> 3992.6057 | O8: =SUM(J8:N8) -> 82591.397 | P8: =IFERROR(VLOOKUP(A8,COGS!$A$204:$N$238,14,FALSE),0) -> -9657.39 | R8: =IFERROR(VLOOKUP(A8,'COGS License'!$A$23:$N$34,14,FALSE),0) -> -415.06412
A9: Canterra Seeds | B9: Canada | C9: =IFERROR(VLOOKUP(A9,'Annual Maintenance'!$A$1:$G$41,7,FALSE),0) -> 62095.212 | D9: =-IFERROR(VLOOKUP(A9,'PS Pivot'!$B$5:$O$39,14,FALSE),0) -> 19640.28 | E9: =IFERROR(VLOOKUP(A9,Licenses!$A$4:$N$25,14,FALSE),0) -> 14016.59 | F9: =IFERROR(VLOOKUP(A9,'IFRS15 Licenses'!$U$10:$AH$26,14,FALSE),0) -> 5751.166 | H9: =SUM(C9:G9) -> 101503.25 | J9: =IFERROR(VLOOKUP(A9,'Annual Maintenance'!$A$1:$N$41,14,FALSE),0) -> 82024.538 | K9: =IFERROR(VLOOKUP(A9,'PS Pivot'!$B$35:$O$56,14,FALSE),0) -> -25933.726 | L9: =IFERROR(VLOOKUP(A9,Licenses!$A$35:$N$53,14,FALSE),0) -> 18602.402 | M9: =IFERROR(VLOOKUP(A9,'IFRS15 Licenses'!$U$37:$AH$51,14,FALSE),0) -> 7664.9633 | O9: =SUM(J9:N9) -> 82358.177 | P9: =IFERROR(VLOOKUP(A9,COGS!$A$204:$N$238,14,FALSE),0) -> -3331.9444 | R9: =IFERROR(VLOOKUP(A9,'COGS License'!$A$23:$N$34,14,FALSE),0) -> 0
A10: COFCO International | B10: UK | C10: =IFERROR(VLOOKUP(A10,'Annual Maintenance'!$A$1:$G$41,7,FALSE),0) -> 62529.616 | D10: =-IFERROR(VLOOKUP(A10,'PS Pivot'!$B$5:$O$39,14,FALSE),0) -> 6849.7 | E10: =IFERROR(VLOOKUP(A10,Licenses!$A$4:$N$25,14,FALSE),0) -> 0 | F10: =IFERROR(VLOOKUP(A10,'IFRS15 Licenses'!$U$10:$AH$26,14,FALSE),0) -> 0 | H10: =SUM(C10:G10) -> 69379.316 | J10: =IFERROR(VLOOKUP(A10,'Annual Maintenance'!$A$1:$N$41,14,FALSE),0) -> 82579.986 | K10: =IFERROR(VLOOKUP(A10,'PS Pivot'!$B$35:$O$56,14,FALSE),0) -> -8768.1393 | L10: =IFERROR(VLOOKUP(A10,Licenses!$A$35:$N$53,14,FALSE),0) -> 0 | M10: =IFERROR(VLOOKUP(A10,'IFRS15 Licenses'!$U$37:$AH$51,14,FALSE),0) -> 0 | O10: =SUM(J10:N10) -> 73811.847 | P10: =IFERROR(VLOOKUP(A10,COGS!$A$204:$N$238,14,FALSE),0) -> -16786.695 | R10: =IFERROR(VLOOKUP(A10,'COGS License'!$A$23:$N$34,14,FALSE),0) -> 0
A11: Cope Seeds | B11: UK | C11: =IFERROR(VLOOKUP(A11,'Annual Maintenance'!$A$1:$G$41,7,FALSE),0) -> 0 | D11: =-IFERROR(VLOOKUP(A11,'PS Pivot'!$B$5:$O$39,14,FALSE),0) -> 2520 | E11: =IFERROR(VLOOKUP(A11,Licenses!$A$4:$N$25,14,FALSE),0) -> 0 | F11: =IFERROR(VLOOKUP(A11,'IFRS15 Licenses'!$U$10:$AH$26,14,FALSE),0) -> 0 | H11: =SUM(C11:G11) -> 2520 | K11: =IFERROR(VLOOKUP(A11,'PS Pivot'!$B$35:$O$56,14,FALSE),0) -> -3390.6515 | L11: =IFERROR(VLOOKUP(A11,Licenses!$A$35:$N$53,14,FALSE),0) -> 0 | M11: =IFERROR(VLOOKUP(A11,'IFRS15 Licenses'!$U$37:$AH$51,14,FALSE),0) -> 0 | O11: =SUM(J11:N11) -> -3390.6515 | P11: =IFERROR(VLOOKUP(A11,COGS!$A$204:$N$238,14,FALSE),0) -> 0 | R11: =IFERROR(VLOOKUP(A11,'COGS License'!$A$23:$N$34,14,FALSE),0) -> 0
A12: Confluence Genetics | B12: USA | C12: =IFERROR(VLOOKUP(A12,'Annual Maintenance'!$A$1:$G$41,7,FALSE),0) -> 0 | D12: =-IFERROR(VLOOKUP(A12,'PS Pivot'!$B$5:$O$39,14,FALSE),0) -> 26212.614 | E12: =IFERROR(VLOOKUP(A12,Licenses!$A$4:$N$25,14,FALSE),0) -> 8404.03 | F12: =IFERROR(VLOOKUP(A12,'IFRS15 Licenses'!$U$10:$AH$26,14,FALSE),0) -> 0 | H12: =SUM(C12:G12) -> 34616.644 | K12: =IFERROR(VLOOKUP(A12,'PS Pivot'!$B$35:$O$56,14,FALSE),0) -> -35116.341 | L12: =IFERROR(VLOOKUP(A12,Licenses!$A$35:$N$53,14,FALSE),0) -> 11115.119 | M12: =IFERROR(VLOOKUP(A12,'IFRS15 Licenses'!$U$37:$AH$51,14,FALSE),0) -> 0 | O12: =SUM(J12:N12) -> -24001.222 | P12: =IFERROR(VLOOKUP(A12,COGS!$A$204:$N$238,14,FALSE),0) -> -0.51428724 | R12: =IFERROR(VLOOKUP(A12,'COGS License'!$A$23:$N$34,14,FALSE),0) -> -7445.7053
A13: Denholm Fish Selling Ltd | B13: UK | C13: =IFERROR(VLOOKUP(A13,'Annual Maintenance'!$A$1:$G$41,7,FALSE),0) -> 55553.323 | D13: =-IFERROR(VLOOKUP(A13,'PS Pivot'!$B$5:$O$39,14,FALSE),0) -> -14337.5 | E13: =IFERROR(VLOOKUP(A13,Licenses!$A$4:$N$25,14,FALSE),0) -> 6109.5 | F13: =IFERROR(VLOOKUP(A13,'IFRS15 Licenses'!$U$10:$AH$26,14,FALSE),0) -> 0 | H13: =SUM(C13:G13) -> 47325.323 | J13: =IFERROR(VLOOKUP(A13,'Annual Maintenance'!$A$1:$N$41,14,FALSE),0) -> 73384.077 | K13: =IFERROR(VLOOKUP(A13,'PS Pivot'!$B$35:$O$56,14,FALSE),0) -> 19122.074 | L13: =IFERROR(VLOOKUP(A13,Licenses!$A$35:$N$53,14,FALSE),0) -> 8377.9003 | M13: =IFERROR(VLOOKUP(A13,'IFRS15 Licenses'!$U$37:$AH$51,14,FALSE),0) -> 0 | O13: =SUM(J13:N13) -> 100884.05 | P13: =IFERROR(VLOOKUP(A13,COGS!$A$204:$N$238,14,FALSE),0) -> -1189.6497 | R13: =IFERROR(VLOOKUP(A13,'COGS License'!$A$23:$N$34,14,FALSE),0) -> 0
A14: DL Seeds | B14: Canada | C14: =IFERROR(VLOOKUP(A14,'Annual Maintenance'!$A$1:$G$41,7,FALSE),0) -> 9008.3644 | D14: =-IFERROR(VLOOKUP(A14,'PS Pivot'!$B$5:$O$39,14,FALSE),0) -> 2027.07 | E14: =IFERROR(VLOOKUP(A14,Licenses!$A$4:$N$25,14,FALSE),0) -> 4604.18 | F14: =IFERROR(VLOOKUP(A14,'IFRS15 Licenses'!$U$10:$AH$26,14,FALSE),0) -> 0 | H14: =SUM(C14:G14) -> 15639.614 | J14: =IFERROR(VLOOKUP(A14,'Annual Maintenance'!$A$1:$N$41,14,FALSE),0) -> 11698.342 | K14: =IFERROR(VLOOKUP(A14,'PS Pivot'!$B$35:$O$56,14,FALSE),0) -> -2752.3801 | L14: =IFERROR(VLOOKUP(A14,Licenses!$A$35:$N$53,14,FALSE),0) -> 6192.7422 | M14: =IFERROR(VLOOKUP(A14,'IFRS15 Licenses'!$U$37:$AH$51,14,FALSE),0) -> 0 | O14: =SUM(J14:N14) -> 15138.704 | P14: =IFERROR(VLOOKUP(A14,COGS!$A$204:$N$238,14,FALSE),0) -> -1334.877 | R14: =IFERROR(VLOOKUP(A14,'COGS License'!$A$23:$N$34,14,FALSE),0) -> 0
A15: Dugdale Nutrition | B15: UK | C15: =IFERROR(VLOOKUP(A15,'Annual Maintenance'!$A$1:$G$41,7,FALSE),0) -> 64354.47 | D15: =-IFERROR(VLOOKUP(A15,'PS Pivot'!$B$5:$O$39,14,FALSE),0) -> 6628 | E15: =IFERROR(VLOOKUP(A15,Licenses!$A$4:$N$25,14,FALSE),0) -> 553.82 | F15: =IFERROR(VLOOKUP(A15,'IFRS15 Licenses'!$U$10:$AH$26,14,FALSE),0) -> 450 | H15: =SUM(C15:G15) -> 71986.29 | J15: =IFERROR(VLOOKUP(A15,'Annual Maintenance'!$A$1:$N$41,14,FALSE),0) -> 85005.466 | K15: =IFERROR(VLOOKUP(A15,'PS Pivot'!$B$35:$O$56,14,FALSE),0) -> -8859.6605 | L15: =IFERROR(VLOOKUP(A15,Licenses!$A$35:$N$53,14,FALSE),0) -> 747.56692 | M15: =IFERROR(VLOOKUP(A15,'IFRS15 Licenses'!$U$37:$AH$51,14,FALSE),0) -> 591.26504 | O15: =SUM(J15:N15) -> 77484.637 | P15: =IFERROR(VLOOKUP(A15,COGS!$A$204:$N$238,14,FALSE),0) -> -5441.817 | R15: =IFERROR(VLOOKUP(A15,'COGS License'!$A$23:$N$34,14,FALSE),0) -> -451.29112
A16: Elevator | B16: UK | C16: =IFERROR(VLOOKUP(A16,'Annual Maintenance'!$A$1:$G$41,7,FALSE),0) -> 10882.453 | D16: =-IFERROR(VLOOKUP(A16,'PS Pivot'!$B$5:$O$39,14,FALSE),0) -> 0 | E16: =IFERROR(VLOOKUP(A16,Licenses!$A$4:$N$25,14,FALSE),0) -> 0 | F16: =IFERROR(VLOOKUP(A16,'IFRS15 Licenses'!$U$10:$AH$26,14,FALSE),0) -> 0 | H16: =SUM(C16:G16) -> 10882.453 | J16: =IFERROR(VLOOKUP(A16,'Annual Maintenance'!$A$1:$N$41,14,FALSE),0) -> 14371.647 | K16: =IFERROR(VLOOKUP(A16,'PS Pivot'!$B$35:$O$56,14,FALSE),0) -> 0 | L16: =IFERROR(VLOOKUP(A16,Licenses!$A$35:$N$53,14,FALSE),0) -> 0 | M16: =IFERROR(VLOOKUP(A16,'IFRS15 Licenses'!$U$37:$AH$51,14,FALSE),0) -> 0 | O16: =SUM(J16:N16) -> 14371.647 | P16: =IFERROR(VLOOKUP(A16,COGS!$A$204:$N$238,14,FALSE),0) -> -9402.8672 | R16: =IFERROR(VLOOKUP(A16,'COGS License'!$A$23:$N$34,14,FALSE),0) -> 0
A17: E B Bradshaws | K17: =IFERROR(VLOOKUP(A17,'PS Pivot'!$B$35:$O$56,14,FALSE),0) -> 0 | L17: =IFERROR(VLOOKUP(A17,Licenses!$A$35:$N$53,14,FALSE),0) -> 0 | M17: =IFERROR(VLOOKUP(A17,'IFRS15 Licenses'!$U$37:$AH$51,14,FALSE),0) -> 0 | O17: =SUM(J17:N17) -> 0 | P17: =IFERROR(VLOOKUP(A17,COGS!$A$204:$N$238,14,FALSE),0) -> -843.94888 | R17: =IFERROR(VLOOKUP(A17,'COGS License'!$A$23:$N$34,14,FALSE),0) -> 0
A18: Fram Farmers | B18: UK | C18: =IFERROR(VLOOKUP(A18,'Annual Maintenance'!$A$1:$G$41,7,FALSE),0) -> 29460.291 | D18: =-IFERROR(VLOOKUP(A18,'PS Pivot'!$B$5:$O$39,14,FALSE),0) -> 296 | E18: =IFERROR(VLOOKUP(A18,Licenses!$A$4:$N$25,14,FALSE),0) -> 3796.28 | F18: =IFERROR(VLOOKUP(A18,'IFRS15 Licenses'!$U$10:$AH$26,14,FALSE),0) -> 8139 | H18: =SUM(C18:G18) -> 41691.571 | J18: =IFERROR(VLOOKUP(A18,'Annual Maintenance'!$A$1:$N$41,14,FALSE),0) -> 38924.124 | K18: =IFERROR(VLOOKUP(A18,'PS Pivot'!$B$35:$O$56,14,FALSE),0) -> -397.84946 | L18: =IFERROR(VLOOKUP(A18,Licenses!$A$35:$N$53,14,FALSE),0) -> 5020.9367 | M18: =IFERROR(VLOOKUP(A18,'IFRS15 Licenses'!$U$37:$AH$51,14,FALSE),0) -> 10104.408 | O18: =SUM(J18:N18) -> 53651.619 | P18: =IFERROR(VLOOKUP(A18,COGS!$A$204:$N$238,14,FALSE),0) -> -1392.8744 | R18: =IFERROR(VLOOKUP(A18,'COGS License'!$A$23:$N$34,14,FALSE),0) -> 0
A19: Frontier Agriculture | B19: UK | C19: =IFERROR(VLOOKUP(A19,'Annual Maintenance'!$A$1:$G$41,7,FALSE),0)+520000 -> 2177709.5 | D19: =-IFERROR(VLOOKUP(A19,'PS Pivot'!$B$5:$O$39,14,FALSE),0) -> 0 | E19: =IFERROR(VLOOKUP(A19,Licenses!$A$4:$N$25,14,FALSE),0) -> 0 | F19: =IFERROR(VLOOKUP(A19,'IFRS15 Licenses'!$U$10:$AH$26,14,FALSE),0) -> 0 | H19: =SUM(C19:G19) -> 2177709.5 | J19: =IFERROR(VLOOKUP(A19,'Annual Maintenance'!$A$1:$N$41,14,FALSE),0) -> 2189263.4 | K19: =IFERROR(VLOOKUP(A19,'PS Pivot'!$B$35:$O$56,14,FALSE),0) -> 0 | L19: =IFERROR(VLOOKUP(A19,Licenses!$A$35:$N$53,14,FALSE),0) -> 0 | M19: =IFERROR(VLOOKUP(A19,'IFRS15 Licenses'!$U$37:$AH$51,14,FALSE),0) -> 0 | O19: =SUM(J19:N19) -> 2189263.4 | P19: =IFERROR(VLOOKUP(A19,COGS!$A$204:$N$238,14,FALSE),0) -> -174087.37 | R19: =IFERROR(VLOOKUP(A19,'COGS License'!$A$23:$N$34,14,FALSE),0) -> 0
A20: G Williams Seeds | B20: UK | C20: =IFERROR(VLOOKUP(A20,'Annual Maintenance'!$A$1:$G$41,7,FALSE),0) -> 20776.969 | D20: =-IFERROR(VLOOKUP(A20,'PS Pivot'!$B$5:$O$39,14,FALSE),0) -> 7844 | E20: =IFERROR(VLOOKUP(A20,Licenses!$A$4:$N$25,14,FALSE),0) -> 786.47 | F20: =IFERROR(VLOOKUP(A20,'IFRS15 Licenses'!$U$10:$AH$26,14,FALSE),0) -> 0 | H20: =SUM(C20:G20) -> 29407.439 | J20: =IFERROR(VLOOKUP(A20,'Annual Maintenance'!$A$1:$N$41,14,FALSE),0) -> 27449.414 | K20: =IFERROR(VLOOKUP(A20,'PS Pivot'!$B$35:$O$56,14,FALSE),0) -> -10513.151 | L20: =IFERROR(VLOOKUP(A20,Licenses!$A$35:$N$53,14,FALSE),0) -> 1050.7562 | M20: =IFERROR(VLOOKUP(A20,'IFRS15 Licenses'!$U$37:$AH$51,14,FALSE),0) -> 0 | O20: =SUM(J20:N20) -> 17987.02 | P20: =IFERROR(VLOOKUP(A20,COGS!$A$204:$N$238,14,FALSE),0) -> -2284.7658 | R20: =IFERROR(VLOOKUP(A20,'COGS License'!$A$23:$N$34,14,FALSE),0) -> -642.41136
A21: Glasson Grain | B21: UK | C21: =IFERROR(VLOOKUP(A21,'Annual Maintenance'!$A$1:$G$41,7,FALSE),0) -> 98202.427 | D21: =-IFERROR(VLOOKUP(A21,'PS Pivot'!$B$5:$O$39,14,FALSE),0) -> 24009.603 | E21: =IFERROR(VLOOKUP(A21,Licenses!$A$4:$N$25,14,FALSE),0) -> 4258.77 | F21: =IFERROR(VLOOKUP(A21,'IFRS15 Licenses'!$U$10:$AH$26,14,FALSE),0) -> 350 | H21: =SUM(C21:G21) -> 126820.8 | J21: =IFERROR(VLOOKUP(A21,'Annual Maintenance'!$A$1:$N$41,14,FALSE),0) -> 129721.69 | K21: =IFERROR(VLOOKUP(A21,'PS Pivot'!$B$35:$O$56,14,FALSE),0) -> -32332.611 | L21: =IFERROR(VLOOKUP(A21,Licenses!$A$35:$N$53,14,FALSE),0) -> 5840.0115 | M21: =IFERROR(VLOOKUP(A21,'IFRS15 Licenses'!$U$37:$AH$51,14,FALSE),0) -> 459.87281 | O21: =SUM(J21:N21) -> 103688.96 | P21: =IFERROR(VLOOKUP(A21,COGS!$A$204:$N$238,14,FALSE),0) -> -16129.282 | R21: =IFERROR(VLOOKUP(A21,'COGS License'!$A$23:$N$34,14,FALSE),0) -> -4153.609
A22: Gover Horowitz | B22: UK | C22: =IFERROR(VLOOKUP(A22,'Annual Maintenance'!$A$1:$G$41,7,FALSE),0) -> 10386.781 | D22: =-IFERROR(VLOOKUP(A22,'PS Pivot'!$B$5:$O$39,14,FALSE),0) -> 0 | E22: =IFERROR(VLOOKUP(A22,Licenses!$A$4:$N$25,14,FALSE),0) -> 0 | F22: =IFERROR(VLOOKUP(A22,'IFRS15 Licenses'!$U$10:$AH$26,14,FALSE),0) -> 0 | H22: =SUM(C22:G22) -> 10386.781 | J22: =IFERROR(VLOOKUP(A22,'Annual Maintenance'!$A$1:$N$41,14,FALSE),0) -> 13718.317 | K22: =IFERROR(VLOOKUP(A22,'PS Pivot'!$B$35:$O$56,14,FALSE),0) -> 0 | L22: =IFERROR(VLOOKUP(A22,Licenses!$A$35:$N$53,14,FALSE),0) -> 0 | M22: =IFERROR(VLOOKUP(A22,'IFRS15 Licenses'!$U$37:$AH$51,14,FALSE),0) -> 0 | O22: =SUM(J22:N22) -> 13718.317 | P22: =IFERROR(VLOOKUP(A22,COGS!$A$204:$N$238,14,FALSE),0) -> -489.92733 | R22: =IFERROR(VLOOKUP(A22,'COGS License'!$A$23:$N$34,14,FALSE),0) -> 0
A23: Grainco | B23: UK | C23: =IFERROR(VLOOKUP(A23,'Annual Maintenance'!$A$1:$G$41,7,FALSE),0) -> 94530.098 | D23: =-IFERROR(VLOOKUP(A23,'PS Pivot'!$B$5:$O$39,14,FALSE),0) -> 9994.6 | E23: =IFERROR(VLOOKUP(A23,Licenses!$A$4:$N$25,14,FALSE),0) -> 7510.77 | F23: =IFERROR(VLOOKUP(A23,'IFRS15 Licenses'!$U$10:$AH$26,14,FALSE),0) -> 0 | H23: =SUM(C23:G23) -> 112035.47 | J23: =IFERROR(VLOOKUP(A23,'Annual Maintenance'!$A$1:$N$41,14,FALSE),0) -> 124842.02 | K23: =IFERROR(VLOOKUP(A23,'PS Pivot'!$B$35:$O$56,14,FALSE),0) -> -13098.999 | L23: =IFERROR(VLOOKUP(A23,Licenses!$A$35:$N$53,14,FALSE),0) -> 9901.1603 | M23: =IFERROR(VLOOKUP(A23,'IFRS15 Licenses'!$U$37:$AH$51,14,FALSE),0) -> 0 | O23: =SUM(J23:N23) -> 121644.18 | P23: =IFERROR(VLOOKUP(A23,COGS!$A$204:$N$238,14,FALSE),0) -> -11966.405 | R23: =IFERROR(VLOOKUP(A23,'COGS License'!$A$23:$N$34,14,FALSE),0) -> -1482.402
A24: H J Lea | B24: UK | C24: =IFERROR(VLOOKUP(A24,'Annual Maintenance'!$A$1:$G$41,7,FALSE),0) -> 82017.101 | D24: =-IFERROR(VLOOKUP(A24,'PS Pivot'!$B$5:$O$39,14,FALSE),0) -> 4365 | E24: =IFERROR(VLOOKUP(A24,Licenses!$A$4:$N$25,14,FALSE),0) -> 0 | F24: =IFERROR(VLOOKUP(A24,'IFRS15 Licenses'!$U$10:$AH$26,14,FALSE),0) -> 1000 | H24: =SUM(C24:G24) -> 87382.101 | J24: =IFERROR(VLOOKUP(A24,'Annual Maintenance'!$A$1:$N$41,14,FALSE),0) -> 108214.26 | K24: =IFERROR(VLOOKUP(A24,'PS Pivot'!$B$35:$O$56,14,FALSE),0) -> -5543.214 | L24: =IFERROR(VLOOKUP(A24,Licenses!$A$35:$N$53,14,FALSE),0) -> 0 | M24: =IFERROR(VLOOKUP(A24,'IFRS15 Licenses'!$U$37:$AH$51,14,FALSE),0) -> 1293.4603 | O24: =SUM(J24:N24) -> 103964.5 | P24: =IFERROR(VLOOKUP(A24,COGS!$A$204:$N$238,14,FALSE),0) -> -10440.949 | R24: =IFERROR(VLOOKUP(A24,'COGS License'!$A$23:$N$34,14,FALSE),0) -> 0
A25: Harlow Agriculture | B25: UK | C25: =IFERROR(VLOOKUP(A25,'Annual Maintenance'!$A$1:$G$41,7,FALSE),0) -> 92092.844 | D25: =-IFERROR(VLOOKUP(A25,'PS Pivot'!$B$5:$O$39,14,FALSE),0) -> 0 | E25: =IFERROR(VLOOKUP(A25,Licenses!$A$4:$N$25,14,FALSE),0) -> 0 | F25: =IFERROR(VLOOKUP(A25,'IFRS15 Licenses'!$U$10:$AH$26,14,FALSE),0) -> 522.2 | H25: =SUM(C25:G25) -> 92615.044 | J25: =IFERROR(VLOOKUP(A25,'Annual Maintenance'!$A$1:$N$41,14,FALSE),0) -> 121654.52 | K25: =IFERROR(VLOOKUP(A25,'PS Pivot'!$B$35:$O$56,14,FALSE),0) -> 0 | L25: =IFERROR(VLOOKUP(A25,Licenses!$A$35:$N$53,14,FALSE),0) -> 0 | M25: =IFERROR(VLOOKUP(A25,'IFRS15 Licenses'!$U$37:$AH$51,14,FALSE),0) -> 690.96924 | O25: =SUM(J25:N25) -> 122345.49 | P25: =IFERROR(VLOOKUP(A25,COGS!$A$204:$N$238,14,FALSE),0) -> -11611.247 | R25: =IFERROR(VLOOKUP(A25,'COGS License'!$A$23:$N$34,14,FALSE),0) -> 0
A26: Humphrey Feeds | B26: UK | C26: =IFERROR(VLOOKUP(A26,'Annual Maintenance'!$A$1:$G$41,7,FALSE),0) -> 36582.778 | D26: =-IFERROR(VLOOKUP(A26,'PS Pivot'!$B$5:$O$39,14,FALSE),0) -> 0 | E26: =IFERROR(VLOOKUP(A26,Licenses!$A$4:$N$25,14,FALSE),0) -> 0 | F26: =IFERROR(VLOOKUP(A26,'IFRS15 Licenses'!$U$10:$AH$26,14,FALSE),0) -> 0 | H26: =SUM(C26:G26) -> 36582.778 | J26: =IFERROR(VLOOKUP(A26,'Annual Maintenance'!$A$1:$N$41,14,FALSE),0) -> 48823.803 | K26: =IFERROR(VLOOKUP(A26,'PS Pivot'!$B$35:$O$56,14,FALSE),0) -> 0 | L26: =IFERROR(VLOOKUP(A26,Licenses!$A$35:$N$53,14,FALSE),0) -> 0 | M26: =IFERROR(VLOOKUP(A26,'IFRS15 Licenses'!$U$37:$AH$51,14,FALSE),0) -> 0 | O26: =SUM(J26:N26) -> 48823.803 | P26: =IFERROR(VLOOKUP(A26,COGS!$A$204:$N$238,14,FALSE),0) -> -9113.4149 | R26: =IFERROR(VLOOKUP(A26,'COGS License'!$A$23:$N$34,14,FALSE),0) -> 0
A27: Integra Petrochemicals | B27: Singapore | C27: =IFERROR(VLOOKUP(A27,'Annual Maintenance'!$A$1:$G$41,7,FALSE),0) -> 12790.307 | D27: =-IFERROR(VLOOKUP(A27,'PS Pivot'!$B$5:$O$39,14,FALSE),0) -> 0 | E27: =IFERROR(VLOOKUP(A27,Licenses!$A$4:$N$25,14,FALSE),0) -> 0 | F27: =IFERROR(VLOOKUP(A27,'IFRS15 Licenses'!$U$10:$AH$26,14,FALSE),0) -> 0 | H27: =SUM(C27:G27) -> 12790.307 | J27: =IFERROR(VLOOKUP(A27,'Annual Maintenance'!$A$1:$N$41,14,FALSE),0) -> 16852.115 | K27: =IFERROR(VLOOKUP(A27,'PS Pivot'!$B$35:$O$56,14,FALSE),0) -> 0 | L27: =IFERROR(VLOOKUP(A27,Licenses!$A$35:$N$53,14,FALSE),0) -> 0 | M27: =IFERROR(VLOOKUP(A27,'IFRS15 Licenses'!$U$37:$AH$51,14,FALSE),0) -> 0 | O27: =SUM(J27:N27) -> 16852.115 | P27: =IFERROR(VLOOKUP(A27,COGS!$A$204:$N$238,14,FALSE),0) -> -7250.5217 | R27: =IFERROR(VLOOKUP(A27,'COGS License'!$A$23:$N$34,14,FALSE),0) -> 0
A28: J E Porter | B28: UK | C28: =IFERROR(VLOOKUP(A28,'Annual Maintenance'!$A$1:$G$41,7,FALSE),0) -> 48.485962 | D28: =-IFERROR(VLOOKUP(A28,'PS Pivot'!$B$5:$O$39,14,FALSE),0) -> 0 | E28: =IFERROR(VLOOKUP(A28,Licenses!$A$4:$N$25,14,FALSE),0) -> 0 | F28: =IFERROR(VLOOKUP(A28,'IFRS15 Licenses'!$U$10:$AH$26,14,FALSE),0) -> 2000 | H28: =SUM(C28:G28) -> 2048.486 | J28: =IFERROR(VLOOKUP(A28,'Annual Maintenance'!$A$1:$N$41,14,FALSE),0) -> 62.698495 | K28: =IFERROR(VLOOKUP(A28,'PS Pivot'!$B$35:$O$56,14,FALSE),0) -> 0 | L28: =IFERROR(VLOOKUP(A28,Licenses!$A$35:$N$53,14,FALSE),0) -> 0 | M28: =IFERROR(VLOOKUP(A28,'IFRS15 Licenses'!$U$37:$AH$51,14,FALSE),0) -> 2586.5064 | O28: =SUM(J28:N28) -> 2649.2049 | P28: =IFERROR(VLOOKUP(A28,COGS!$A$204:$N$238,14,FALSE),0) -> -36.56371 | R28: =IFERROR(VLOOKUP(A28,'COGS License'!$A$23:$N$34,14,FALSE),0) -> 0
A29: J Stobart & Sons | B29: UK | C29: =IFERROR(VLOOKUP(A29,'Annual Maintenance'!$A$1:$G$41,7,FALSE),0) -> 18684.074 | D29: =-IFERROR(VLOOKUP(A29,'PS Pivot'!$B$5:$O$39,14,FALSE),0) -> 1950 | E29: =IFERROR(VLOOKUP(A29,Licenses!$A$4:$N$25,14,FALSE),0) -> 545.41 | F29: =IFERROR(VLOOKUP(A29,'IFRS15 Licenses'!$U$10:$AH$26,14,FALSE),0) -> 500 | H29: =SUM(C29:G29) -> 21679.484 | J29: =IFERROR(VLOOKUP(A29,'Annual Maintenance'!$A$1:$N$41,14,FALSE),0) -> 24680.946 | K29: =IFERROR(VLOOKUP(A29,'PS Pivot'!$B$35:$O$56,14,FALSE),0) -> -2454.7755 | L29: =IFERROR(VLOOKUP(A29,Licenses!$A$35:$N$53,14,FALSE),0) -> 733.07796 | M29: =IFERROR(VLOOKUP(A29,'IFRS15 Licenses'!$U$37:$AH$51,14,FALSE),0) -> 656.96116 | O29: =SUM(J29:N29) -> 23616.21 | P29: =IFERROR(VLOOKUP(A29,COGS!$A$204:$N$238,14,FALSE),0) -> -6151.4492 | R29: =IFERROR(VLOOKUP(A29,'COGS License'!$A$23:$N$34,14,FALSE),0) -> -450.20161
A30: London Metals Ltd | B30: UK | C30: =IFERROR(VLOOKUP(A30,'Annual Maintenance'!$A$1:$G$41,7,FALSE),0) -> 29008.939 | D30: =-IFERROR(VLOOKUP(A30,'PS Pivot'!$B$5:$O$39,14,FALSE),0) -> 0 | E30: =IFERROR(VLOOKUP(A30,Licenses!$A$4:$N$25,14,FALSE),0) -> 0 | F30: =IFERROR(VLOOKUP(A30,'IFRS15 Licenses'!$U$10:$AH$26,14,FALSE),0) -> 0 | H30: =SUM(C30:G30) -> 29008.939 | J30: =IFERROR(VLOOKUP(A30,'Annual Maintenance'!$A$1:$N$41,14,FALSE),0) -> 38311.778 | K30: =IFERROR(VLOOKUP(A30,'PS Pivot'!$B$35:$O$56,14,FALSE),0) -> 0 | L30: =IFERROR(VLOOKUP(A30,Licenses!$A$35:$N$53,14,FALSE),0) -> 0 | M30: =IFERROR(VLOOKUP(A30,'IFRS15 Licenses'!$U$37:$AH$51,14,FALSE),0) -> 0 | O30: =SUM(J30:N30) -> 38311.778 | P30: =IFERROR(VLOOKUP(A30,COGS!$A$204:$N$238,14,FALSE),0) -> -3246.9289 | R30: =IFERROR(VLOOKUP(A30,'COGS License'!$A$23:$N$34,14,FALSE),0) -> 0
A31: Morning Foods | B31: UK | C31: =IFERROR(VLOOKUP(A31,'Annual Maintenance'!$A$1:$G$41,7,FALSE),0) -> 0 | D31: =-IFERROR(VLOOKUP(A31,'PS Pivot'!$B$5:$O$39,14,FALSE),0) -> 0 | E31: =IFERROR(VLOOKUP(A31,Licenses!$A$4:$N$25,14,FALSE),0) -> 2489.66 | F31: =IFERROR(VLOOKUP(A31,'IFRS15 Licenses'!$U$10:$AH$26,14,FALSE),0) -> 0 | H31: =SUM(C31:G31) -> 2489.66 | J31: =IFERROR(VLOOKUP(A31,'Annual Maintenance'!$A$1:$N$41,14,FALSE),0) -> 0 | K31: =IFERROR(VLOOKUP(A31,'PS Pivot'!$B$35:$O$56,14,FALSE),0) -> 0 | L31: =IFERROR(VLOOKUP(A31,Licenses!$A$35:$N$53,14,FALSE),0) -> 3090.8639 | M31: =IFERROR(VLOOKUP(A31,'IFRS15 Licenses'!$U$37:$AH$51,14,FALSE),0) -> 0 | O31: =SUM(J31:N31) -> 3090.8639 | P31: =IFERROR(VLOOKUP(A31,COGS!$A$204:$N$238,14,FALSE),0) -> 0 | R31: =IFERROR(VLOOKUP(A31,'COGS License'!$A$23:$N$34,14,FALSE),0) -> 0
... A43: Wynnstay Group | B43: UK | C43: =IFERROR(VLOOKUP(A43,'Annual Maintenance'!$A$1:$G$41,7,FALSE),0) -> 168704.17 | D43: =-IFERROR(VLOOKUP(A43,'PS Pivot'!$B$5:$O$39,14,FALSE),0) -> 0 | E43: =IFERROR(VLOOKUP(A43,Licenses!$A$4:$N$25,14,FALSE),0) -> 0 | F43: =IFERROR(VLOOKUP(A43,'IFRS15 Licenses'!$U$10:$AH$26,14,FALSE),0) -> 307.3 | H43: =SUM(C43:G43) -> 169011.47 | J43: =IFERROR(VLOOKUP(A43,'Annual Maintenance'!$A$1:$N$41,14,FALSE),0) -> 222784.75 | K43: =IFERROR(VLOOKUP(A43,'PS Pivot'!$B$35:$O$56,14,FALSE),0) -> 0 | L43: =IFERROR(VLOOKUP(A43,Licenses!$A$35:$N$53,14,FALSE),0) -> 0 | M43: =IFERROR(VLOOKUP(A43,'IFRS15 Licenses'!$U$37:$AH$51,14,FALSE),0) -> 413.32652 | O43: =SUM(J43:N43) -> 223198.07 | P43: =IFERROR(VLOOKUP(A43,COGS!$A$204:$N$238,14,FALSE),0) -> -79029.882 | R43: =IFERROR(VLOOKUP(A43,'COGS License'!$A$23:$N$34,14,FALSE),0) -> 0
E44: =IFERROR(VLOOKUP(A44,Licenses!$A$4:$N$25,14,FALSE),0) -> 0 | F44: =IFERROR(VLOOKUP(A44,'IFRS15 Licenses'!$U$10:$AH$26,14,FALSE),0) -> 0 | H44: =SUM(C44:G44) -> 0
A45: Total | C45: =SUM(C4:C43) -> 5469416.5 | D45: =SUM(D4:D43) -> 313342.2 | E45: =SUM(E4:E43) -> 127309.38 | F45: =SUM(F4:F44) -> 71532.5 | H45: =SUM(C45:G45) -> 5981600.6 | J45: =SUM(J4:J44) -> 6536804.9 | K45: =SUM(K4:K44) -> -415245.8 | L45: =SUM(L4:L44) -> 168655.36 | M45: =SUM(M4:M44) -> 93858.738 | N45: =SUM(N4:N44) -> 0 | O45: =SUM(O4:O44) -> 6384073.2 | P45: =SUM(P4:P44) -> -584770.7 | R45: =SUM(R4:R44) -> -17599.002
A49: UK | B49: =SUMIF($B$4:$B$43,A49,$H$4:$H$43) -> 5120353.7 | C49: =B49/$B$54 -> 0.85601731
A50: USA | B50: =SUMIF($B$4:$B$43,A50,$H$4:$H$43) -> 539503.86 | C50: =B50/$B$54 -> 0.090193895
A51: Canada | B51: =SUMIF($B$4:$B$43,A51,$H$4:$H$43) -> 117142.86 | C51: =B51/$B$54 -> 0.019583866
A52: Netherlands | B52: =SUMIF($B$4:$B$43,A52,$H$4:$H$43) -> 191809.9 | C52: =B52/$B$54 -> 0.032066651
A53: Singapore | B53: =SUMIF($B$4:$B$43,A53,$H$4:$H$43) -> 12790.307 | C53: =B53/$B$54 -> 0.0021382749
B54: =SUM(B49:B53) -> 5981600.6 | C54: =SUM(C49:C53) -> 1

Sheet COGS License
A2: Row Labels | B2: Sum of Jan-25 | C2: Sum of Feb-25 | D2: Sum of Mar-25 | E2: Sum of Apr-25 | F2: Sum of May-25 | G2: Sum of Jun-25 | H2: Sum of Jul-25 | I2: Sum of Aug-25 | J2: Sum of Sep-25 | K2: Sum of Oct-25 | L2: Sum of Nov-25 | M2: Sum of Dec-25 | N2: Sum of Total Income 2025
A3: North Herts Farmers | E3: -246.29 | N3: -246.29
A4: Barenbrug | B4: -334.33 | N4: -334.33
A5: Confluence Genetics | H5: -5720 | J5: 5720 | L5: -5720 | N5: -5720
A6: Dugdale Nutrition | I6: -334.33 | N6: -334.33
A7: G Williams Seeds | F7: -477.62 | N7: -477.62
A8: Glasson Grain | H8: -3139.09 | N8: -3139.09
A9: Grainco | B9: -1194.06 | N9: -1194.06
A10: J Stobart & Sons | J10: -334.95 | N10: -334.95
A11: Openfield | K11: -574.41 | N11: -574.41
A12: Robin Appel | M12: -396.6 | N12: -396.6
A13: Saxon Agriculture | E13: -334.33 | N13: -334.33
A14: Scott & Newman | D14: -382.1 | N14: -382.1
A15: Grand Total | B15: -1528.39 | D15: -382.1 | E15: -580.62 | F15: -477.62 | H15: -8859.09 | I15: -334.33 | J15: 5385.05 | K15: -574.41 | L15: -5720 | M15: -396.6 | N15: -13468.11
B16: 1528 | C16: 0 | D16: 382 | E16: 581 | F16: 478 | G16: 0 | H16: 8859 | I16: 334 | J16: 5385 | K16: 574 | L16: 5720 | M16: 397
B17: =B16+B15 -> -0.39 | C17: =C16+C15 -> 0 | D17: =D16+D15 -> -0.1 | E17: =E16+E15 -> 0.38 | F17: =F16+F15 -> 0.38 | G17: =G16+G15 -> 0 | H17: =H16+H15 -> -0.09 | I17: =I16+I15 -> -0.33 | J17: =J16-J15 -> -0.05 | K17: =K16+K15 -> -0.41 | L17: =L16+L15 -> 0 | M17: =M16+M15 -> 0.4
A22: FX RATE | B22: 0.80549 | C22: 0.79437 | D22: 0.77312 | E22: 0.74848 | F22: 0.74348 | G22: 0.72924 | H22: 0.75575 | I22: 0.74083 | J22: 0.744 | K22: 0.76108 | L22: 0.75609 | M22: 0.74322
A23: North Herts Farmers | B23: =B3/$B$22 -> 0 | C23: =C3/$C$22 -> 0 | D23: =D3/$D$22 -> 0 | E23: =E3/$E$22 -> -329.05355 | F23: =F3/$F$22 -> 0 | G23: =G3/$G$22 -> 0 | H23: =H3/$H$22 -> 0 | I23: =I3/$I$22 -> 0 | J23: =J3/$J$22 -> 0 | K23: =K3/$K$22 -> 0 | L23: =L3/$L$22 -> 0 | M23: =M3/$M$22 -> 0 | N23: =SUM(B23:M23) -> -329.05355
A24: Barenbrug | B24: =B4/$B$22 -> -415.06412 | C24: =C4/$C$22 -> 0 | D24: =D4/$D$22 -> 0 | E24: =E4/$E$22 -> 0 | F24: =F4/$F$22 -> 0 | G24: =G4/$G$22 -> 0 | H24: =H4/$H$22 -> 0 | I24: =I4/$I$22 -> 0 | J24: =J4/$J$22 -> 0 | K24: =K4/$K$22 -> 0 | L24: =L4/$L$22 -> 0 | M24: =M4/$M$22 -> 0 | N24: =SUM(B24:M24) -> -415.06412
A25: Confluence Genetics | B25: =B5/$B$22 -> 0 | C25: =C5/$C$22 -> 0 | D25: =D5/$D$22 -> 0 | E25: =E5/$E$22 -> 0 | F25: =F5/$F$22 -> 0 | G25: =G5/$G$22 -> 0 | H25: =H5/$H$22 -> -7568.6404 | I25: =I5/$I$22 -> 0 | J25: =J5/$J$22 -> 7688.172 | K25: =K5/$K$22 -> 0 | L25: =L5/$L$22 -> -7565.2369 | M25: =M5/$M$22 -> 0 | N25: =SUM(B25:M25) -> -7445.7053
A26: Dugdale Nutrition | B26: =B6/$B$22 -> 0 | C26: =C6/$C$22 -> 0 | D26: =D6/$D$22 -> 0 | E26: =E6/$E$22 -> 0 | F26: =F6/$F$22 -> 0 | G26: =G6/$G$22 -> 0 | H26: =H6/$H$22 -> 0 | I26: =I6/$I$22 -> -451.29112 | J26: =J6/$J$22 -> 0 | K26: =K6/$K$22 -> 0 | L26: =L6/$L$22 -> 0 | M26: =M6/$M$22 -> 0 | N26: =SUM(B26:M26) -> -451.29112
A27: G Williams Seeds | B27: =B7/$B$22 -> 0 | C27: =C7/$C$22 -> 0 | D27: =D7/$D$22 -> 0 | E27: =E7/$E$22 -> 0 | F27: =F7/$F$22 -> -642.41136 | G27: =G7/$G$22 -> 0 | H27: =H7/$H$22 -> 0 | I27: =I7/$I$22 -> 0 | J27: =J7/$J$22 -> 0 | K27: =K7/$K$22 -> 0 | L27: =L7/$L$22 -> 0 | M27: =M7/$M$22 -> 0 | N27: =SUM(B27:M27) -> -642.41136
A28: Glasson Grain | B28: =B8/$B$22 -> 0 | C28: =C8/$C$22 -> 0 | D28: =D8/$D$22 -> 0 | E28: =E8/$E$22 -> 0 | F28: =F8/$F$22 -> 0 | G28: =G8/$G$22 -> 0 | H28: =H8/$H$22 -> -4153.609 | I28: =I8/$I$22 -> 0 | J28: =J8/$J$22 -> 0 | K28: =K8/$K$22 -> 0 | L28: =L8/$L$22 -> 0 | M28: =M8/$M$22 -> 0 | N28: =SUM(B28:M28) -> -4153.609
A29: Grainco | B29: =B9/$B$22 -> -1482.402 | C29: =C9/$C$22 -> 0 | D29: =D9/$D$22 -> 0 | E29: =E9/$E$22 -> 0 | F29: =F9/$F$22 -> 0 | G29: =G9/$G$22 -> 0 | H29: =H9/$H$22 -> 0 | I29: =I9/$I$22 -> 0 | J29: =J9/$J$22 -> 0 | K29: =K9/$K$22 -> 0 | L29: =L9/$L$22 -> 0 | M29: =M9/$M$22 -> 0 | N29: =SUM(B29:M29) -> -1482.402
A30: J Stobart & Sons | B30: =B10/$B$22 -> 0 | C30: =C10/$C$22 -> 0 | D30: =D10/$D$22 -> 0 | E30: =E10/$E$22 -> 0 | F30: =F10/$F$22 -> 0 | G30: =G10/$G$22 -> 0 | H30: =H10/$H$22 -> 0 | I30: =I10/$I$22 -> 0 | J30: =J10/$J$22 -> -450.20161 | K30: =K10/$K$22 -> 0 | L30: =L10/$L$22 -> 0 | M30: =M10/$M$22 -> 0 | N30: =SUM(B30:M30) -> -450.20161
A31: Openfield | B31: =B11/$B$22 -> 0 | C31: =C11/$C$22 -> 0 | D31: =D11/$D$22 -> 0 | E31: =E11/$E$22 -> 0 | F31: =F11/$F$22 -> 0 | G31: =G11/$G$22 -> 0 | H31: =H11/$H$22 -> 0 | I31: =I11/$I$22 -> 0 | J31: =J11/$J$22 -> 0 | K31: =K11/$K$22 -> -754.73012 | L31: =L11/$L$22 -> 0 | M31: =M11/$M$22 -> 0 | N31: =SUM(B31:M31) -> -754.73012
A32: Robin Appel | B32: =B12/$B$22 -> 0 | C32: =C12/$C$22 -> 0 | D32: =D12/$D$22 -> 0 | E32: =E12/$E$22 -> 0 | F32: =F12/$F$22 -> 0 | G32: =G12/$G$22 -> 0 | H32: =H12/$H$22 -> 0 | I32: =I12/$I$22 -> 0 | J32: =J12/$J$22 -> 0 | K32: =K12/$K$22 -> 0 | L32: =L12/$L$22 -> 0 | M32: =M12/$M$22 -> -533.62396 | N32: =SUM(B32:M32) -> -533.62396
A33: Saxon Agriculture | B33: =B13/$B$22 -> 0 | C33: =C13/$C$22 -> 0 | D33: =D13/$D$22 -> 0 | E33: =E13/$E$22 -> -446.6786 | F33: =F13/$F$22 -> 0 | G33: =G13/$G$22 -> 0 | H33: =H13/$H$22 -> 0 | I33: =I13/$I$22 -> 0 | J33: =J13/$J$22 -> 0 | K33: =K13/$K$22 -> 0 | L33: =L13/$L$22 -> 0 | M33: =M13/$M$22 -> 0 | N33: =SUM(B33:M33) -> -446.6786
A34: Scott & Newman | B34: =B14/$B$22 -> 0 | C34: =C14/$C$22 -> 0 | D34: =D14/$D$22 -> -494.23117 | E34: =E14/$E$22 -> 0 | F34: =F14/$F$22 -> 0 | G34: =G14/$G$22 -> 0 | H34: =H14/$H$22 -> 0 | I34: =I14/$I$22 -> 0 | J34: =J14/$J$22 -> 0 | K34: =K14/$K$22 -> 0 | L34: =L14/$L$22 -> 0 | M34: =M14/$M$22 -> 0 | N34: =SUM(B34:M34) -> -494.23117
N36: =SUM(N23:N35) -> -17599.002

Sheet COGS
A1: Location | B1: Customer Level | C1: Customer | D1: Inv Number | E1: Description | F1: Inv Value | G1: Start Date | H1: End Date | I1: No Of Days | J1: Def rev remaining @ 31.12.24 (B/F) | K1: 45658 | L1: 45689 | M1: 45717 | N1: 45748 | O1: 45778 | P1: 45809 | Q1: 45839 | R1: 45870 | S1: 45901 | T1: 45931 | U1: 45962 | V1: 45992 | W1: Total Income 2025 | X1: Invoiced YTD | Y1: Amount Deferred YTD Rev
K2: 31 | L2: 29 | M2: 31 | N2: 30 | O2: 31 | P2: 30 | Q2: 31 | R2: 31 | S2: 30 | T2: 31 | U2: 30 | V2: 31
A3: Primetics GEN NA | B3: SEED | C3: Barenbrug | D3: RCT000901 | E3: Annual Progress Maintenance | F3: -5230.5 | G3: 45561 | H3: 45925 | I3: 364 | J3: -3836.658 | K3: -445.45467 | L3: -416.71566 | M3: -445.45467 | N3: -431.08516 | O3: -445.45467 | P3: -431.08516 | Q3: -445.45467 | R3: -445.45467 | S3: -330.5 | W3: -3836.6593
A4: Primetics GEN NA | B4: SEED | C4: Barenbrug | D4: INV-175452 | E4: Annual Open Accounts Maintenance | F4: -2270.3 | G4: 45323 | H4: 45688 | I4: 365 | J4: -186.6 | K4: -186.6 | W4: -186.6
A5: Primetics GEN NA | B5: SEED | C5: Barenbrug | D5: INV-256165 | E5: Annual Open Accounts Maintenance | F5: -2004.12 | G5: 45689 | H5: 46053 | I5: 364 | J5: -2004.12 | L5: -159.6689 | M5: -170.68055 | N5: -165.17473 | O5: -170.68055 | P5: -165.17473 | Q5: -170.68055 | R5: -170.68055 | S5: -165.17473 | T5: -170.68055 | U5: -165.17473 | V5: -170.68055 | W5: -1844.4511
A6: Primetics GEN NA | B6: SEED | C6: Barenbrug | D6: RCT000935 | E6: Annual Progress Maintenance | F6: -5486.25 | G6: 45926 | H6: 46290 | I6: 364 | S6: -60.288462 | T6: -467.23558 | U6: -452.16346 | V6: -467.23558 | W6: -1446.9231 | X6: -5486.25
A7: Primetics GEN NA | B7: SEED | C7: Canterra Seeds | D7: RCT000880 | E7: Annual Progress Maintenance | F7: -2510.18 | G7: 45313 | H7: 45679 | I7: 366 | J7: -150.88514 | K7: -150.89 | W7: -150.89
A8: Primetics GEN NA | B8: SEED | C8: Canterra Seeds | D8: RCT000911 | E8: Annual Progress Maintenance | F8: -2510.18 | G8: 45679 | H8: 46043 | I8: 364 | K8: -62.06489 | L8: -199.98687 | M8: -213.77907 | N8: -206.88297 | O8: -213.77907 | P8: -206.88297 | Q8: -213.77907 | R8: -213.77907 | S8: -206.88297 | T8: -213.77907 | U8: -206.88297 | V8: -213.77907 | W8: -2372.258 | X8: -2510.18
A9: PRTH | B9: KIT | C9: COFCO International | D9: UK00095422 | E9: Annual Microsoft GP Maintenance | F9: -12461.42 | G9: 45668 | H9: 46032 | I9: 364 | J9: -12461.42 | K9: -684.69341 | L9: -992.80544 | M9: -1061.2748 | N9: -1027.0401 | O9: -1061.2748 | P9: -1027.0401 | Q9: -1061.2748 | R9: -1061.2748 | S9: -1027.0401 | T9: -1061.2748 | U9: -1027.0401 | V9: -1061.2748 | W9: -12153.308
A10: PRTH | B10: KIT | C10: COFCO International | D10: UK00081499 | E10: Annual Microsoft GP Maintenance | F10: -9882.68 | G10: 45302 | H10: 45667 | I10: 365 | J10: -270.75836 | K10: -270.76 | W10: -270.76
A11: PRTH | B11: KIT | C11: COFCO International | D11: INV276588 | E11: Smartlist builder | F11: -1276.8 | G11: 45959 | H11: 46323 | I11: 364 | U11: -112.24615 | V11: -108.73846 | W11: -220.98462 | X11: -1276.8
A12: PRTH | B12: KIT | C12: COFCO International | D12: INV276589 | E12: Smartlist builder | F12: -500 | G12: 45980 | H12: 46344 | I12: 364 | U12: -15.10989 | V12: -42.582418 | W12: -57.692308 | X12: -500
A13: PRTH | B13: KIT | C13: COFCO International | D13: UK00112807 | E13: Annual Microsoft GP Maintenance | F13: -13117.28 | G13: 46033 | H13: 46397 | I13: 364 | W13: 0 | X13: -13117.28
A14: Primetics GEN NA | B14: SEED | C14: Confluence Genetics | D14: RCT000929 | E14: Annual Progress Maintenance | F14: -1188.01 | G14: 45869 | H14: 46233 | I14: 364 | Q14: -3.2637637 | R14: -101.17668 | S14: 104.44 | W14: -0.00043956044 | X14: -1188.01
A15: PRTH | B15: KIT | C15: Denholm Fish Selling Ltd | D15: 129170 | E15: Annual NCC Deposit | F15: -1835 | G15: 45474 | H15: 45838 | I15: 365 | J15: -909.9589 | K15: -155.84932 | L15: -145.79452 | M15: -155.84932 | N15: -150.82192 | O15: -155.84932 | P15: -145.79 | W15: -909.95438
A16: Primetics GEN NA | B16: SEED | C16: DL Seeds | D16: UK00082155 | E16: Annual Microsoft GP Maintenance | F16: -812.24 | G16: 45340 | H16: 45705 | I16: 365 | J16: -106.81512 | K16: -68.984767 | L16: -37.83 | W16: -106.81477
A17: Primetics GEN NA | B17: SEED | C17: DL Seeds | D17: RCT000891 | E17: Annual Progress Maintenance | F17: -153 | G17: 45426 | H17: 45790 | I17: 364 | J17: -56.324176 | K17: -13.03022 | L17: -12.18956 | M17: -13.03022 | N17: -12.60989 | O17: -5.46 | W17: -56.31989
A18: Primetics GEN NA | B18: SEED | C18: DL Seeds | D18: RCT000924 | E18: Annual Progress Maintenance | F18: -58.58 | G18: 45791 | H18: 46155 | I18: 364 | O18: -2.7358791 | P18: -4.828022 | Q18: -4.988956 | R18: -4.988956 | S18: -4.828022 | T18: -4.988956 | U18: -4.828022 | V18: -4.988956 | W18: -37.175769 | X18: -58.58
A19: Primetics GEN NA | B19: SEED | C19: DL Seeds | D19: UK00096030 | E19: Annual Microsoft GP Maintenance | F19: -918.55 | G19: 45706 | H19: 46070 | I19: 364 | P19: -335.62404 | Q19: -78.228159 | R19: -78.228159 | S19: -75.70467 | T19: -78.228159 | U19: -75.70467 | V19: -78.228159 | W19: -799.94602 | X19: -918.55
A20: PRTH | B20: KIT | C20: Elevator | D20: UK00095427 | E20: Annual Microsoft GP Maintenance | F20: -7129.73 | G20: 45668 | H20: 46032 | I20: 364 | J20: -7129.74 | K20: -391.74341 | L20: -568.02794 | M20: -607.20228 | N20: -587.61511 | O20: -607.20228 | P20: -587.61511 | Q20: -607.20228 | R20: -607.20228 | S20: -587.61511 | T20: -607.20228 | U20: -587.61511 | V20: -607.20228 | W20: -6953.4455
A21: PRTH | B21: KIT | C21: Elevator | D21: UK00080835 | E21: Annual Microsoft GP Maintenance | F21: -5986.94 | G21: 45302 | H21: 45667 | I21: 365 | J21: -164.02575 | K21: -164.03 | W21: -164.03
A22: PRTH | B22: KIT | C22: Elevator | D22: UK00112809 | E22: Annual Microsoft GP Maintenance | F22: -7504.99 | G22: 46033 | H22: 46397 | I22: 364 | W22: 0 | X22: -7504.99
A23: PRTH | B23: KIT | C23: Gover Horowitz | D23: INV271621 | E23: Smartlist builder | F23: -1388.8 | G23: 45933 | H23: 46268 | I23: 335 | T23: -116.07881 | U23: -124.37015 | V23: -128.51582 | W23: -368.96478 | X23: -1388.8
A24: PRTH | B24: KIT | C24: Integra Petrochemicals | D24: UK00081514 | E24: Annual Microsoft GP Maintenance | F24: -4576.5 | G24: 45303 | H24: 45668 | I24: 365 | J24: -137.92192 | K24: -137.92 | W24: -137.92
A25: PRTH | B25: KIT | C25: Integra Petrochemicals | D25: UK00095435 | E25: Annual Microsoft GP Maintenance | F25: -5501.25 | G25: 45669 | H25: 46033 | I25: 364 | K25: -287.15316 | L25: -438.2864 | M25: -468.51305 | N25: -453.39973 | O25: -468.51305 | P25: -453.39973 | Q25: -468.51305 | R25: -468.51305 | S25: -453.39973 | T25: -468.51305 | U25: -453.39973 | V25: -468.51305 | W25: -5350.1168 | X25: -5501.25
A26: PRTH | B26: KIT | C26: London Metals Ltd | D26: UK00095426 | E26: Annual Microsoft Maintenance | F26: -2355.01 | G26: 45668 | H26: 46032 | I26: 364 | J26: -2355.01 | K26: -129.39615 | L26: -187.62442 | M26: -200.56404 | N26: -194.09423 | O26: -200.56404 | P26: -194.09423 | Q26: -200.56404 | R26: -200.56404 | S26: -194.09423 | T26: -200.56404 | U26: -194.09423 | V26: -200.56404 | W26: -2296.7817
A27: PRTH | B27: KIT | C27: London Metals Ltd | D27: UK00081510 | E27: Annual Microsoft Maintenance | F27: -1977.53 | G27: 45302 | H27: 45667 | I27: 365 | J27: -54.178904 | K27: -54.18 | W27: -54.18
A28: PRTH | B28: KIT | C28: London Metals Ltd | D28: 607269 | E28: Advanced Smartlist Maintenance | F28: -155.45 | G28: 45505 | H28: 45869 | I28: 364 | J28: -90.109753 | K28: -13.238874 | L28: -12.384753 | M28: -13.238874 | N28: -12.811813 | O28: -13.238874 | P28: -12.811813 | Q28: -12.38 | W28: -90.105
A29: PRTH | B29: KIT | C29: London Metals Ltd | D29: 608410 | E29: Advanced Smartlist Maintenance | F29: -118.54 | G29: 45969 | H29: 46333 | I29: 364 | U29: -7.1645055 | V29: -10.09544 | W29: -17.259945 | X29: -118.54
A30: PRTH | B30: KIT | C30: London Metals Ltd | D30: UK00112806 | E30: Annual Microsoft Maintenance | F30: -2478.96 | G30: 46033 | H30: 46397 | I30: 364 | W30: 0 | X30: -2478.96
A31: PRTH | B31: KIT | C31: Oxbow Coal | D31: UK00095429 | E31: Annual Microsoft GP Maintenance | F31: -6885.45 | G31: 45668 | H31: 46032 | I31: 364 | J31: -6885.46 | K31: -378.32143 | L31: -548.56607 | M31: -586.39821 | N31: -567.48214 | O31: -586.39821 | P31: -567.48214 | Q31: -586.39821 | R31: -586.39821 | S31: -567.48214 | T31: -586.39821 | U31: -567.48214 | V31: -586.39821 | W31: -6715.2054
A32: PRTH | B32: KIT | C32: Oxbow Coal | D32: UK00081499 | E32: Annual Microsoft GP Maintenance | F32: -6000.7 | G32: 45302 | H32: 45667 | I32: 365 | J32: -164.40274 | K32: -164.4 | W32: -164.4
A33: PRTH | B33: KIT | C33: Oxbow Coal | D33: INVMHL116414 | E33: Annual M-Hance Maintenance | F33: -376.23 | G33: 45505 | H33: 45869 | I33: 364 | J33: -218.08937 | K33: -32.041566 | L33: -29.974368 | M33: -32.041566 | N33: -31.007967 | O33: -32.041566 | P33: -31.007967 | Q33: -29.97 | W33: -218.085
A34: PRTH | B34: KIT | C34: Oxbow Coal | D34: EU_IN80594 | E34: Annual M-Hance Maintenance | F34: -362.45 | G34: 45657 | H34: 46021 | I34: 364 | J34: -361.4742 | K34: -30.867995 | L34: -28.876511 | M34: -30.867995 | N34: -29.872253 | O34: -30.867995 | P34: -29.872253 | Q34: -30.867995 | R34: -30.867995 | S34: -29.872253 | T34: -30.867995 | U34: -29.872253 | V34: -27.9 | W34: -361.47349
A35: PRTH | B35: KIT | C35: Oxbow Coal | D35: EU_IN80595 | E35: Annual M-Hance Maintenance | F35: -359.97 | G35: 45657 | H35: 46021 | I35: 364 | J35: -358.98107 | K35: -30.656786 | L35: -28.678929 | M35: -30.656786 | N35: -29.667857 | O35: -30.656786 | P35: -29.667857 | Q35: -30.656786 | R35: -30.656786 | S35: -29.667857 | T35: -30.656786 | U35: -29.667857 | V35: -27.69 | W35: -358.98107
A36: PRTH | B36: KIT | C36: Oxbow Coal | D36: 601577 | E36: Advanced Smartlist Maintenance | F36: -126.37 | G36: 45413 | H36: 45777 | I36: 364 | J36: -41.313269 | K36: -10.76228 | L36: -10.06794 | M36: -10.76228 | N36: -9.72 | W36: -41.3125
A37: PRTH | B37: KIT | C37: Oxbow Coal | D37: 607762 | E37: Advanced Smartlist Maintenance | F37: -126.61 | G37: 45759 | H37: 46123 | I37: 364 | N37: -6.2609341 | O37: -10.78272 | P37: -10.43489 | Q37: -10.78272 | R37: -10.78272 | S37: -10.43489 | T37: -10.78272 | U37: -10.43489 | V37: -10.78272 | W37: -91.479203 | X37: -126.61
A38: PRTH | B38: KIT | C38: Oxbow Coal | D38: INVMHL120169 | E38: Annual M-Hance Maintenance | F38: -395.04 | G38: 45931 | H38: 46295 | I38: 364 | T38: -33.643516 | U38: -32.558242 | V38: -33.643516 | W38: -99.845275 | X38: -395.04
A39: PRTH | B39: KIT | C39: Oxbow Coal | D39: UK00112805 | E39: Annual Microsoft GP Maintenance | F39: -7623.63 | G39: 46033 | H39: 46397 | I39: 364 | W39: 0 | X39: -7623.63
