Workbook

Sheet BPC Check
A1: Revenue Type | B1: Amount | C1: BPC | D1: Variance
A2: Maintenance | B2: ='Deferred Maintenance'!AA51 -> 2739365.1 | C2: 2133853.4 | D2: =B2-C2 -> 605511.73
A3: 3rd Party Maint | B3: ='3rd Party Maintenance'!AA45 -> 178875.82 | C3: 130966.08 | D3: =B3-C3 -> 47909.736
A4: Hosting | B4: =Hosting!AA38 -> 591425.97 | C4: 460483.53 | D4: =B4-C4 -> 130942.44
A5: PS | B5: =PS!AA53 -> 711077.97 | C5: =374650.81+469779.47 -> 844430.28 | D5: =B5-C5 -> -133352.31
A6: License | B6: =Licence!AA52 -> 241612.42 | C6: 209063.37 | D6: =B6-C6 -> 32549.048
A7: Hardware/Flowthrough | B7: 375.72 | C7: 375.72 | D7: =B7-C7 -> 0
A8: Total Revs 2021 | B8: =SUM(B2:B7) -> 4462733 | C8: =SUM(C2:C7) -> 3779172.4 | D8: =SUM(D2:D7) -> 683560.65
A11: Ireland | B11: =C8-B12 -> #REF!
A12: UK | B12: =GETPIVOTDATA("Amount",'Consolidated Revenue'!$D$2,"Customer","Denis Brinicombe")+GETPIVOTDATA("Amount",'Consolidated Revenue'!$D$2,"Customer","Denis Brinicombe Group")+GETPIVOTDATA("Amount",'Consolidated Revenue'!$D$2,"Customer","East Coast Viners")+GETPIVOTDATA("Amount",'Consolidated Revenue'!$D$2,"Customer","OMSCO") -> #REF!
A14: Total | B14: =SUM(B11:B13) -> #REF!

Sheet Customers sorted by Revs 22
A1: Customer | B1: Amount
A2: Glanbia | B2: 506750.97
A3: Heat Merchants | B3: 279561.24
A4: Aurivo Co-Op Society | B4: 196069.76
A5: Arrabawn Co-Op Society | B5: 190597.76
A6: East Coast Viners | B6: 175401.07
A7: Dairygold Co-Op | B7: 167267.15
A8: Lakeland Dairies | B8: 147268.71
A9: Drinagh Co-Op | B9: 141864.45
A10: Bandon Co-Op | B10: 137071.36
A11: Lisavaird Co-Op | B11: 134300.56
A12: North Cork Co-Op | B12: 130824.86
A13: M.D O'Shea | B13: 127732.93
... A47: Newmarket Co-Op | B47: 1153.3541

Sheet Consolidated Revenue
A1: Customer | B1: Amount
A2: Arrabawn Co-Op Society | B2: 13380.452 | D2: Row Labels | E2: Sum of Amount
A3: Aurivo Co-Op Society | B3: 2100.0703 | D3: Arrabawn Co-Op Society | E3: 190597.76
A4: Aurivo Co-Op Society | B4: 0 | D4: Aurivo Co-Op Society | E4: 196069.76
A5: BallyJamesDuff Co-Op | B5: 0 | D5: BallyJamesDuff Co-Op | E5: 17701.797
A6: Bandon Co-Op | B6: 5555.9744 | D6: Bandon Co-Op | E6: 137071.36
A7: Bandon Vale Cheese | B7: 2551.7331 | D7: Bandon Vale Cheese | E7: 15688.142
A8: Barryroe Co-Op | B8: 0 | D8: Barryroe Co-Op | E8: 102327.43
A9: Brett Brothers | B9: 845.48721 | D9: Brett Brothers | E9: 51317.681
A10: Callan Co-Op | B10: 5185.6009 | D10: Callan Co-Op | E10: 30175.774
A11: Carbery | B11: 0 | D11: Carbery | E11: 43355.952
A12: Centenary Thurles Co-Op | B12: 0 | D12: Centenary Thurles Co-Op | E12: 52194.313
A13: Centenary Thurles Feed & Grain | B13: 0 | D13: Centenary Thurles Feed & Grain | E13: 16778.728
A14: Centenary Thurles Fresh Milk | B14: 0 | D14: Centenary Thurles Fresh Milk | E14: 8933.2532
... A52: Arrabawn Co-Op Society | B52: 44205.374 | D52: Grand Total | E52: 3779172.4
A53: Aurivo Co-Op Society | B53: 25410.286
A54: Aurivo Co-Op Society | B54: 0
A55: BallyJamesDuff Co-Op | B55: 0
A56: Bandon Co-Op | B56: 14208.375
A57: Bandon Vale Cheese | B57: 134.07354
A58: Barryroe Co-Op | B58: 11532.682
A59: Brett Brothers | B59: 1039.717
A60: Callan Co-Op | B60: 2747.579
A61: Carbery | B61: 25816.401
A62: Centenary Thurles Co-Op | B62: 13132.502
A63: Centenary Thurles Feed & Grain | B63: 1004.0161
A64: Centenary Thurles Fresh Milk | B64: 0
... A224: East Coast Viners | B224: 375.72

Sheet Recurring Revenue Euros
A1: 3rd Party Maint | D1: Maintenance | G1: Hosting
A3: Row Labels | B3: Sum of Consolidated Eur | D3: Row Labels | E3: Sum of Cons EUR | G3: Row Labels | H3: Sum of Consildated Eur | K3: Customer | L3: Amount
A4: Arrabawn | B4: 9651.45 | D4: Arrabawn | E4: 139228.06 | G4: Arrabawn | H4: 10567.26 | K4: (blank) | L4: 2423519.2
A5: Aurivo | B5: 19128.44 | D5: Aurivo | E5: 170337.22 | G5: BallyJamesDuff | H5: 8074.24 | K5: Adj | L5: -0.5 | N5: Row Labels | O5: Sum of Amount
A6: Aurivo NI | B6: 387.73 | D6: Aurivo NI | E6: 7666.1 | G6: Bandon Co-Op | H6: 30534.76 | K6: Adj | L6: 0 | N6: Arrabawn | O6: 159446.77
A7: BallyJamesDuff | B7: 516.95 | D7: BallyJamesDuff | E7: 11829.446 | G7: Barryroe Co-Op | H7: 28225.96 | K7: Arrabawn | L7: 9651.45 | N7: Aurivo | O7: 197519.47
A8: Bandon Co-Op | B8: 5817.83 | D8: Bandon Co-Op | E8: 98598.38 | G8: Brett Brothers | H8: 8380.75 | K8: Arrabawn | L8: 139228.06 | N8: BallyJamesDuff | O8: 20420.636
A9: Bandon Vale Cheese | B9: 260.11 | D9: Bandon Vale Cheese | E9: 14425.44 | G9: Callan Co-Op | H9: 5828.88 | K9: Arrabawn | L9: 10567.26 | N9: Bandon Co-Op | O9: 134950.97
A10: Barryroe Co-op | B10: 4404.83 | D10: Barryroe Co-Op | E10: 73404.02 | G10: Carbery | H10: 6899.14 | K10: Aurivo | L10: 19128.44 | N10: Bandon Vale Cheese | O10: 14685.55
A11: Callan Co-Op | B11: 639.1 | D11: Brett Brothers | E11: 48255.92 | G11: Centenary Thurles Co-Op | H11: 6852.29 | K11: Aurivo | L11: 170337.2 | N11: Barryroe Co-op | O11: 106034.81
A12: Carbery | B12: 778.09 | D12: Callan Co-Op | E12: 29512.68 | G12: Dan O'Connor | H12: 1663.48 | K12: Aurivo | L12: 387.73 | N12: Brett Brothers | O12: 56636.67
A13: Centenary Thurles Co-Op | B13: 1691.89 | D13: Carbery | E13: 17409.4 | G13: Denis Brinicombe | H13: 19633.03 | K13: Aurivo | L13: 7666.1 | N13: Callan Co-Op | O13: 35980.66
A14: Centenary Thurles Stores | B14: 4931.43 | D14: Centenary Thurles Co-Op | E14: 37525.12 | G14: Drinagh Co-Op | H14: 25977.19 | K14: BallyJamesDuff | L14: 516.95 | N14: Carbery | O14: 7677.23
A15: Dan O'Connor | B15: 88.69 | D15: Centenary Thurles Feed & Grain | E15: 17695.96 | G15: Drinagh Dairies | H15: 1647.01 | K15: BallyJamesDuff | L15: 11829.446 | N15: Carbery | O15: 17409.4
A16: Denis Brinicombe | B16: 1869.56 | D16: Centenary Thurles Fresh Milk | E16: 10021.24 | G16: Heat Merchants | H16: 123019.94 | K16: BallyJamesDuff | L16: 8074.24 | N16: Centenary Thurles Co-Op | O16: 46069.3
A17: Drinagh Co-Op | B17: 5882.16 | D17: Centenary Thurles Stores | E17: 41181.34 | G17: Hopkins | H17: 6899.14 | K17: Bandon Co-Op | L17: 5817.83 | N17: Centenary Thurles Feed & Grain | O17: 17695.96
... A40: Strathroy Dairy | B40: 641.41 | D40: Morris DIY | E40: 43950.24 | G40: Grand Total | H40: 523479.21 | K40: Centenary Thurles Stores | L40: 41181.34 | N40: McDonnell Bros | O40: 55308.31
A41: T&A Building | B41: 881.19 | D41: North Cork | E41: 78296.98 | K41: Dan O'Connor | L41: 88.69 | N41: McDonogh | O41: 36230.68
A42: Tirlan | B42: 33235.04 | D42: Organic Herd | E42: 21375.12 | K42: Dan O'Connor | L42: 38313.1 | N42: Morris DIY | O42: 46324
A43: Wallaces | B43: 1603.68 | D43: Peter Curran | E43: 31446.02 | K43: Dan O'Connor | L43: 1663.48 | N43: North Cork | O43: 91347.04
A44: Brett Brother | B44: 2805.91 | D44: Richard Boyle | E44: 64598.7 | K44: Denis Brinicombe | L44: 1869.56 | N44: Organic Herd | O44: 44671.04
A45: Kiernan Milling | B45: 3192.0011 | D45: Smiths Building | E45: 15550.88 | K45: Denis Brinicombe | L45: 31133.3 | N45: Peter Curran | O45: 42624.75
A46: Grand Total | B46: 158131.04 | D46: Smiths Tools | E46: 1434.19 | K46: Denis Brinicombe | L46: 19633.03 | N46: Richard Boyle | O46: 84269.66
D47: Strathroy Dairy | E47: 13958.33 | K47: Drinagh Co-Op | L47: 5882.16 | N47: Smiths Building | O47: 28457.79
D48: T&A Building | E48: 20778.08 | K48: Drinagh Co-Op | L48: 111777.58 | N48: Smiths Tools | O48: 2182.95
D49: Tirlan | E49: 349646.53 | K49: Drinagh Co-Op | L49: 25977.19 | N49: Strathroy Dairy | O49: 20779
D50: Wallaces | E50: 58557.1 | K50: Drinagh Dairies | L50: 33319.5 | N50: T&A Building | O50: 30843.56
D51: Kiernan Milling | E51: 12300 | K51: Drinagh Dairies | L51: 1647.01 | N51: Tirlan | O51: 400710.64
D52: Adj | E52: 0 | K52: East Coast Viners | L52: 3203.43 | N52: Adj | O52: -0.5
D53: Grand Total | E53: 2423519.2 | K53: East Coast Viners | L53: 31047.49 | N53: Brett Brother | O53: 2805.91
K54: Heat Merchants | L54: 13788.91 | N54: Kiernan Milling | O54: 15492.001
K55: Heat Merchants | L55: 161591.86 | N55: Wallaces Homevalue Hardware | O55: 60599.11
K56: Heat Merchants | L56: 123019.94 | N56: Grand Total | O56: 3105129.4
K57: Hopkins | L57: 359.48
K58: Hopkins | L58: 17595.65
K59: Hopkins | L59: 6899.14
K60: ICMSA | L60: 3247.59
K61: ICMSA | L61: 8660.24
K62: Irish International Traders | L62: 1133
K63: Irish International Traders | L63: 10594.79
...

Sheet Recurring Revenue Data
A1: Customer | B1: Amount
A2: Bandon Co-Op | B2: 111426.79
A3: Barryroe Co-Op | B3: 82954.448
A4: Brett Brothers | B4: 54554.246
A5: Callan Co-Op | B5: 33579.615 | G5: Row Labels | H5: Sum of Amount
A6: Centenary Thurles Feed & Grain | B6: 19993.023 | G6: Arrabawn | H6: 180331.79 | M6: Tirlan | N6: 452741.11
A7: Centenary Thurles Fresh Milk | B7: 11322.069 | G7: Aurivo | H7: 223189.75 | M7: Heat Merchants | N7: 337224.14
A8: Centenary Thurles Stores | B8: 46526.973 | G8: Bandon Co-Op | H8: 152509.13 | M8: Aurivo | N8: 223189.75
A9: Denis Brinicombe | B9: 35213.125 | G9: Drinagh Co-Op | H9: 162333.46 | M9: Arrabawn | N9: 180331.79
A10: Drinagh Co-Op | B10: 126328.56 | G10: Heat Merchants | H10: 337224.14 | M10: Drinagh Co-Op | N10: 162333.46
A11: Drinagh Dairies | B11: 37654.623 | G11: Kiernan Milling | H11: 18081.747 | M11: Bandon Co-Op | N11: 152509.13
A12: Heat Merchants | B12: 182616.2 | G12: Lakeland Dairies | H12: 150259.19 | M12: Lakeland Dairies | N12: 150259.19
A13: J.McKenna | B13: 38950.359 | G13: Lisavaird | H13: 136329.13 | M13: Lisavaird | N13: 136329.13
A14: John McCarthy | B14: 24161.494 | G14: M.D O'Shea | H14: 131225.21 | M14: M.D O'Shea | N14: 131225.21
A15: M.D O'Shea | B15: 111418.84 | G15: Tirlan | H15: 452741.11 | M15: Kiernan Milling | N15: 18081.747
A16: Peter Curran | B16: 35527.939 | G16: Grand Total | H16: 1944224.7
A17: Smiths Tools | B17: 1483.0263
A18: T&A Building | B18: 23472.853
A19: BallyJamesDuff | B19: 13364.833
A20: Centenary Thurles Co-Op | B20: 42396.15
A21: Dan O'Connor | B21: 43297.929
A22: Hopkins | B22: 19879.657
A23: ICMSA | B23: 3670.1264
A24: Lee Strand | B24: 47235.868
A25: Lisavaird | B25: 106593.97
A26: Morris DIY | B26: 49655.296
A27: North Cork | B27: 88460.49
A28: Richard Boyle | B28: 72984.075
... A126: Kiernan Milling | B126: 3737.0849

Sheet Revenue Consolidated
A1: Customer | B1: Revenue | U1: 151266.33
A2: Bandon Co-Op | B2: 6574.7744 | T2: Customer | U2: Hosting Revenue | V2: % | W2: Hosting COGs
A3: Barryroe Co-op | B3: 4977.9323 | T3: Tirlan | U3: =_xlfn.XLOOKUP(T3,Summary!$G$40:$G$73,Summary!$H$40:$H$73) -> #N/A | V3: =U3/Summary!$H$75 -> #N/A | W3: =$U$1*V3 -> #N/A
A4: Callan Co-Op | B4: 722.25183 | T4: Heat Merchants | U4: =_xlfn.XLOOKUP(T4,Summary!$G$40:$G$73,Summary!$H$40:$H$73) -> #N/A | V4: =U4/Summary!$H$75 -> #N/A | W4: =$U$1*V4 -> #N/A
A5: Centenary Thurles Stores | B5: 5573.047 | D5: Row Labels | E5: Sum of Revenue | H5: Customer | I5: Amount | J5: Country | K5: 3rd Party COGS | L5: Hosting COGS | M5: Net Revenue | T5: Aurivo Co-Op | U5: 0 | V5: =U5/Summary!$H$75 -> #DIV/0! | W5: =$U$1*V5 -> #DIV/0!
A6: Denis Brinicombe Group | B6: 2112.8041 | D6: AIB Merchant Services | E6: 3975.549 | H6: Tirlan | I6: 601656.03 | J6: Ireland | K6: 1941.0089 | L6: 5043.7386 | M6: =I6-K6-L6 -> 594671.28 | T6: Drinagh Co-Op | U6: =_xlfn.XLOOKUP(T6,Summary!$G$40:$G$73,Summary!$H$40:$H$73) -> #N/A | V6: =U6/Summary!$H$75 -> #N/A | W6: =$U$1*V6 -> #N/A
A7: Drinagh Co-Op | B7: 6647.8783 | D7: Arrabawn Co-Op Society | E7: 333622.81 | H7: Heat Merchants Group | I7: 399481.19 | J7: Ireland | K7: 820.94353 | L7: 34956.537 | M7: =I7-K7-L7 -> 363703.71 | T7: Arrabawn | U7: =_xlfn.XLOOKUP(T7,Summary!$G$40:$G$73,Summary!$H$40:$H$73) -> #N/A | V7: =U7/Summary!$H$75 -> #N/A | W7: =$U$1*V7 -> #N/A
A8: Heat Merchants Group | B8: 15582.953 | D8: Aurivo Co-Op | E8: 249690.63 | H8: Arrabawn Co-Op Society | I8: 333622.81 | J8: Ireland | K8: 1126.0137 | L8: 0 | M8: =I8-K8-L8 -> 332496.79 | T8: Lakeland Dairies | U8: =_xlfn.XLOOKUP(T8,Summary!$G$40:$G$73,Summary!$H$40:$H$73) -> #N/A | V8: =U8/Summary!$H$75 -> #N/A | W8: =$U$1*V8 -> #N/A
A9: J. McKenna Ltd | B9: 1577.3252 | D9: BallyJamesDuff Co-Op | E9: 23073.803 | H9: Aurivo Co-Op | I9: 249690.63 | J9: Ireland | K9: 345.80922 | L9: 7491.3712 | M9: =I9-K9-L9 -> 241853.45 | T9: M.D O'Shea | U9: =_xlfn.XLOOKUP(T9,Summary!$G$40:$G$73,Summary!$H$40:$H$73) -> #N/A | V9: =U9/Summary!$H$75 -> #N/A | W9: =$U$1*V9 -> #N/A
A10: John R. McCarthy | B10: 1718.8938 | D10: Bandon Co-Op | E10: 165745.69 | H10: Kiernan Milling | I10: 234100.25 | J10: Ireland | K10: 529.60411 | L10: 3047.409 | M10: =I10-K10-L10 -> 230523.24 | T10: Bandon Co-Op | U10: =_xlfn.XLOOKUP(T10,Summary!$G$40:$G$73,Summary!$H$40:$H$73) -> #N/A | V10: =U10/Summary!$H$75 -> #N/A | W10: =$U$1*V10 -> #N/A
A11: M.D O'Shea & Sons Ltd | B11: 10723.294 | D11: Bandon Vale Cheese | E11: 16596.253 | H11: Lisavaird Co-Op | I11: 184226.11 | J11: Ireland | K11: 153.21331 | L11: 2641.5506 | M11: =I11-K11-L11 -> 181431.34 | T11: Lisavaird | U11: =_xlfn.XLOOKUP(T11,Summary!$G$40:$G$73,Summary!$H$40:$H$73) -> #N/A | V11: =U11/Summary!$H$75 -> #N/A | W11: =$U$1*V11 -> #N/A
A12: McDonnell Bros Ltd | B12: 2705.2126 | D12: Barryroe Co-op | E12: 126603.07 | H12: Drinagh Co-Op | I12: 179057.25 | J12: Ireland | K12: 513.16291 | L12: 2317.828 | M12: =I12-K12-L12 -> 176226.26 | T12: Barryroe Co-op | U12: =_xlfn.XLOOKUP(T12,Summary!$G$40:$G$73,Summary!$H$40:$H$73) -> #N/A | V12: =U12/Summary!$H$75 -> #N/A | W12: =$U$1*V12 -> #N/A
A13: Peter Curran Electrical | B13: 2001.2173 | D13: Brett Brothers | E13: 85104.007 | H13: Bandon Co-Op | I13: 165745.69 | J13: Ireland | K13: 341.36579 | L13: 8805.6934 | M13: =I13-K13-L13 -> 156598.63
A14: Smith's Tool Hire | B14: 846.17943 | D14: Callan Co-Op | E14: 88253.787 | H14: M.D O'Shea & Sons Ltd | I14: 165195.93 | J14: Ireland | K14: 162.47915 | L14: 6755.4099 | M14: =I14-K14-L14 -> 158278.04
A15: T&A Building | B15: 995.8396 | D15: Carbery Group | E15: 32026.795 | H15: Lakeland Dairies | I15: 160704.37 | J15: Ireland | K15: 262.24797 | L15: 8139.8767 | M15: =I15-K15-L15 -> 152302.25 | U15: 9023.58
A16: BallyJamesDuff Co-Op | B16: 584.20917 | D16: Centenary Thurles Co-Op | E16: 54023.376 | H16: Barryroe Co-op | I16: 126603.07 | J16: Ireland
A17: Centenary Thurles Co-Op | B17: 1912.0179 | D17: Centenary Thurles Feed & Grain | E17: 19993.023 | H17: North Cork Co-Op | I17: 116155.05 | J17: Ireland | T17: Tirlan | U17: 31652.42 | V17: =U17/$T$29 -> 0.21510409 | W17: =$U$15*V17 -> 1941.0089
A18: Dan O'Connor Feeds | B18: 100.22925 | D18: Centenary Thurles Fresh Milk | E18: 11322.069 | H18: Wallaces Homevalue Hardware | I18: 113688.17 | J18: Ireland | T18: Heat Merchants | U18: 13387.29 | V18: =U18/$T$29 -> 0.090977587 | W18: =$U$15*V18 -> 820.94353
A19: East Coast Viners | B19: 3621.295 | D19: Centenary Thurles Stores | E19: 53082.918 | H19: Richard Boyle & Sons Ltd | I19: 96907.329 | J19: Ireland | T19: Aurivo Co-Op | U19: 18362.13 | V19: =U19/$T$29 -> 0.12478569 | W19: =$U$15*V19 -> 1126.0137
A20: Hopkins Homevalue Hardware | B20: 406.28262 | D20: Dan O'Connor Feeds | E20: 45350.946 | H20: Denis Brinicombe Group | I20: 92025.601 | J20: UK | T20: Drinagh Co-Op | U20: 5639.18 | V20: =U20/$T$29 -> 0.038322841 | W20: =$U$15*V20 -> 345.80922
A21: Lee Strand Dairies | B21: 895.74596 | D21: Denis Brinicombe Group | E21: 92025.601 | H21: Callan Co-Op | I21: 88253.787 | J21: Ireland | T21: Arrabawn | U21: 8636.36 | V21: =U21/$T$29 -> 0.058691131 | W21: =$U$15*V21 -> 529.60411
A22: Lisavaird Co-Op | B22: 3262.2018 | D22: Drinagh Co-Op | E22: 179057.25 | H22: Brett Brothers | I22: 85104.007 | J22: Ireland | T22: Lakeland Dairies | U22: 2498.48 | V22: =U22/$T$29 -> 0.016979215 | W22: =$U$15*V22 -> 153.21331
A23: Morris DIY & Building | B23: 2682.6044 | D23: Drinagh Dairies | E23: 39515.922 | H23: Kerry Agribusiness | I23: 78930.962 | J23: Ireland | T23: M.D O'Shea | U23: 8368.25 | V23: =U23/$T$29 -> 0.056869104 | W23: =$U$15*V23 -> 513.16291
A24: North Cork Co-Op | B24: 4615.5971 | D24: East Coast Viners | E24: 66059.099 | H24: East Coast Viners | I24: 66059.099 | J24: UK | T24: Bandon Co-Op | U24: 5566.72 | V24: =U24/$T$29 -> 0.037830416 | W24: =$U$15*V24 -> 341.36579
A25: Richard Boyle & Sons Ltd | B25: 4313.3046 | D25: Heat Merchants Group | E25: 399481.19 | H25: McDonnell Bros Ltd | I25: 65824.662 | J25: Ireland | T25: Lisavaird | U25: 2649.58 | V25: =U25/$T$29 -> 0.018006064 | W25: =$U$15*V25 -> 162.47915
A26: Wallaces Homevalue Hardware | B26: 1811.417 | D26: Hopkins Homevalue Hardware | E26: 28082.711 | H26: Lee Strand Dairies | I26: 61078.842 | J26: Ireland | T26: Barryroe Co-op | U26: 4276.53 | V26: =U26/$T$29 -> 0.02906252 | W26: =$U$15*V26 -> 262.24797
A27: Arrabawn Co-Op Society | B27: 10930.289 | D27: ICMSA | E27: 13457.13 | H27: Morris DIY & Building | I27: 57942.364 | J27: Ireland
A28: Aurivo Co-Op | B28: 21620.609 | D28: Irish International Traders | E28: 13690.924 | H28: Organic Herd | I28: 54033.221 | J28: UK
A29: Aurivo Co-Op | B29: 438.17665 | D29: J. McKenna Ltd | E29: 48783.708 | H29: Centenary Thurles Co-Op | I29: 54023.376 | J29: Ireland | T29: 147149.32
A30: Bandon Vale Cheese | B30: 293.95231 | D30: John R. McCarthy | E30: 33624.146 | H30: Centenary Thurles Stores | I30: 53082.918 | J30: Ireland
A31: Carbery Group | B31: 879.32549 | D31: Joyce Hardware | E31: 0 | H31: J. McKenna Ltd | I31: 48783.708 | J31: Ireland
A32: Irish International Traders | B32: 1280.412 | D32: Kellihers Mills | E32: 12933.315 | H32: Peter Curran Electrical | I32: 48685.313 | J32: Ireland
A33: Kellihers Mills | B33: 541.4798 | D33: Kerry Agribusiness | E33: 78930.962 | H33: Lacpatrick Dairies | I33: 48656.88 | J33: Ireland
A34: Lacpatrick Dairies | B34: 3050.3189 | D34: Kiernan Milling | E34: 234100.25 | H34: Dan O'Connor Feeds | I34: 45350.946 | J34: Ireland
A35: Lakeland Dairies | B35: 1674.1076 | D35: Lacpatrick Dairies | E35: 48656.88 | H35: McDonogh Trade Centre Ltd | I35: 43031.373 | J35: Ireland
A36: Lakeland Dairies | B36: 1234.1567 | D36: Lakeland Dairies | E36: 160704.37 | H36: Drinagh Dairies | I36: 39515.922 | J36: Ireland
A37: McDonogh Trade Centre Ltd | B37: 1639.1647 | D37: Lee Strand Dairies | E37: 61078.842 | H37: T&A Building | I37: 34847.896 | J37: Ireland
A38: Organic Herd | B38: 1705.4342 | D38: Lisavaird Co-Op | E38: 184226.11 | H38: John R. McCarthy | I38: 33624.146 | J38: Ireland
A39: Smith's Building supplies | B39: 1431.7786 | D39: M.D O'Shea & Sons Ltd | E39: 165195.93 | H39: Smith's Building supplies | I39: 32153.92 | J39: Ireland
A40: Strathroy Dairies | B40: 724.86237 | D40: McDonnell Bros Ltd | E40: 65824.662 | H40: Carbery Group | I40: 32026.795 | J40: Ireland | L40: Row Labels | M40: Sum of Amount
...

Sheet Summary
A1: 3rd Party Maint | D1: Maintenance | G1: Hosting | J1: PS | M1: License
A3: Row Labels | B3: Sum of Consol USD | D3: Row Labels | E3: Sum of Consol USD | G3: Row Labels | H3: Sum of Consol USD | J3: Row Labels | K3: Sum of Consol USD | M3: Row Labels | N3: Sum of CONSOL USD
A4: Bandon Co-Op | B4: 6574.7744 | D4: Bandon Co-Op | E4: 111426.79 | G4: Bandon Co-Op | H4: 34507.567 | J4: Arrabawn Co-Op Society | K4: 80968.525 | M4: Arrabawn Co-Op Society | N4: 72322.498
A5: Barryroe Co-op | B5: 4977.9323 | D5: Barryroe Co-Op | E5: 82954.448 | G5: Barryroe Co-Op | H5: 31898.374 | J5: Aurivo Co-Op | K5: 11726.547 | M5: BallyJamesDuff Co-Op | N5: 0
A6: Callan Co-Op | B6: 722.25183 | D6: Brett Brothers | E6: 54554.246 | G6: Brett Brothers | H6: 9471.15 | J6: BallyJamesDuff Co-Op | K6: 0 | M6: Bandon Co-Op | N6: 0
A7: Centenary Thurles Stores | B7: 5573.047 | D7: Callan Co-Op | E7: 33579.615 | G7: Callan Co-Op | H7: 6587.2621 | J7: Bandon Co-Op | K7: 13236.562 | M7: Bandon Vale Cheese | N7: 0
A8: Denis Brinicombe | B8: 2112.8041 | D8: Centenary Thurles Feed & Grain | E8: 19993.023 | G8: Carbery | H8: 7796.7712 | J8: Bandon Vale Cheese | K8: 0 | M8: Barryroe Co-Op | N8: 0
A9: Drinagh Co-Op | B9: 6647.8783 | D9: Centenary Thurles Fresh Milk | E9: 11322.069 | G9: Denis Brinicombe | H9: 22010.503 | J9: Barryroe Co-Op | K9: 6772.3186 | M9: Brett Brothers | N9: 11816.467
A10: Heat Merchants | B10: 15582.953 | D10: Centenary Thurles Stores | E10: 46526.973 | G10: Drinagh Co-Op | H10: 29357.022 | J10: Brett Brothers | K10: 6091.1639 | M10: Callan Co-Op | N10: 28795.07
A11: J.McKenna | B11: 1577.3252 | D11: Denis Brinicombe | E11: 35213.125 | G11: Drinagh Dairies | H11: 1861.2987 | J11: Callan Co-Op | K11: 18569.589 | M11: Carbery Group | N11: 0
A12: John McCarthy | B12: 1718.8938 | D12: Drinagh Co-Op | E12: 126328.56 | G12: Heat Merchants | H12: 139024.99 | J12: Carbery Group | K12: 3676.2018 | M12: Centenary Thurles Co-Op | N12: 0
A13: M.D O'Shea | B13: 10723.294 | D13: Drinagh Dairies | E13: 37654.623 | G13: J.McKenna | H13: 8256.0243 | J13: Centenary Thurles Co-Op | K13: 1971.3829 | M13: Centenary Thurles Feed & Grain | N13: 0
A14: McDonnell Bros | B14: 2705.2126 | D14: Heat Merchants | E14: 182616.2 | G14: John McCarthy | H14: 7743.7578 | J14: Centenary Thurles Feed & Grain | K14: 0 | M14: Centenary Thurles Fresh Milk | N14: 0
A15: Peter Curran | B15: 2001.2173 | D15: J.McKenna | E15: 38950.359 | G15: Lakeland Dairies | H15: 10351.673 | J15: Centenary Thurles Fresh Milk | K15: 0 | M15: Centenary Thurles Stores | N15: 0
... A38: Lakeland Dairies NI | B38: 1234.1567 | D38: Irish International Traders | E38: 11973.254 | G38: Wallaces Homevalue Hardware | H38: 511.21835 | J38: McDonogh Trade Centre Ltd | K38: 2080.7851 | M38: Smith's Building supplies | N38: 0
A39: McDonogh | B39: 1639.1647 | D39: Kelliher Mills | E39: 5036.8461 | G39: (blank) | J39: Mole Avon Town | K39: 1741.796 | M39: Smith's Tool Hire | N39: 0
A40: Organic Herd | B40: 1705.4342 | D40: Kerry | E40: 50281.249 | G40: Grand Total | H40: 591425.97 | J40: Morris DIY & Building | K40: 2975.0049 | M40: Strathroy Dairies | N40: 0
A41: Smiths Building | B41: 1431.7786 | D41: Lacpatrick Dairies | E41: 43704.813 | J41: North Cork Co-Op | K41: 12946.587 | M41: Wallaces Homevalue Hardware | N41: 10982.202
A42: Strathroy Dairy | B42: 724.86237 | D42: Lacpatrick Dairies NI | E42: 1377.5327 | J42: Organic Herd | K42: 3550.135 | M42: Aurivo Co-Op | N42: 14774.338
A43: Tirlan | B43: 37559.174 | D43: Lakeland Dairies | E43: 65443.519 | J43: Peter Curran Electrical | K43: 524.20515 | M43: Lacpatrick | N43: 0
A44: Brett Brother | B44: 3170.9805 | D44: Lakeland Dairies NI | E44: 61204.056 | J44: Richard Boyle & Sons Ltd | K44: 1692.951 | M44: Lakeland | N44: 0
A45: Kiernan Milling | B45: 3737.0849 | D45: McDonnell | E45: 46142.557 | J45: Smith's Building supplies | K45: 0 | M45: ICMSA | N45: 0
A46: Grand Total | B46: 178875.82 | D46: McDonogh | E46: 26741.631 | J46: Smith's Tool Hire | K46: 0 | M46: Kiernan | N46: 37631.882
D47: Organic Herd | E47: 24156.188 | J47: Strathroy Dairies | K47: 0 | M47: Organic Herd | N47: 0
D48: Smiths Building | E48: 17567.721 | J48: Wallaces Homevalue Hardware | K48: 34208.723 | M48: Discount
D49: Strathroy Dairy | E49: 15774.416 | J49: Wolseley | K49: 1955.4489 | M49: AIB Merchant Services | N49: 3383.4459
D50: Tirlan | E50: 395033.16 | J50: AIB Merchant Services | K50: 592.10304 | M50: Tirlan | N50: 0
D51: Kiernan Milling | E51: 14344.662 | J51: Tirlan | K51: 148914.92 | M51: T&A Building | N51: 0
D52: Adj | E52: 0 | J52: Adj | K52: 0 | M52: Grand Total | N52: 241612.42
D53: Grand Total | E53: 2739365.1 | J53: T&A Building | K53: 0
J54: Grand Total | K54: 711077.97

Sheet Deferred Maintenance
A1: Customer | B1: January | C1: February | D1: March | E1: April | F1: May | G1: June | H1: July | I1: August | J1: September | K1: October | L1: November | M1: December | N1: Cons EUR | O1: USD January | P1: USD February | Q1: USD March | R1: USD April | S1: USD May | T1: USD June | U1: USD July | V1: USD August | W1: USD September | X1: USD October | Y1: USD November | Z1: USD December | AA1: Consol USD
A2: Arrabawn | B2: 11498.217 | C2: 10385.486 | D2: 11498.217 | E2: 11127.307 | F2: 11930.951 | G2: 11546.082 | H2: 11967.596 | I2: 12009.806 | J2: 11622.393 | K2: 12009.806 | L2: 11622.393 | M2: 12009.806 | N2: =SUM(B2:M2) -> 139228.06 | O2: =B2/$B$57 -> 11896.389 | P2: =C2/$C$57 -> 10812.245 | Q2: =D2/$D$57 -> 12399.539 | R2: =E2/$E$57 -> 12500.204 | S2: =F2/$F$57 -> 13455.91 | T2: =G2/$G$57 -> 13300.865 | U2: =H2/$H$57 -> 13985.737 | V2: =I2/$I$57 -> 13988.15 | W2: =J2/$J$57 -> 13633.625 | X2: =K2/$K$57 -> 13984.078 | Y2: =L2/$L$57 -> 13435.982 | Z2: =M2/$M$57 -> 14066.629 | AA2: =SUM(O2:Z2) -> 157459.35
A3: Aurivo | B3: 14407.711 | C3: 13188.63 | D3: =14601.6913905693+0.01 -> 14601.701 | E3: 14130.669 | F3: 14601.691 | G3: 14130.669 | H3: 14367.176 | I3: 14367.176 | J3: 13903.719 | K3: 14367.176 | L3: 13903.719 | M3: 14367.176 | N3: =SUM(B3:M3) -> 170337.22 | O3: =B3/$B$57 -> 14906.636 | P3: =C3/$C$57 -> 13730.576 | Q3: =D3/$D$57 -> 15746.3 | R3: =E3/$E$57 -> 15874.124 | S3: =F3/$F$57 -> 16468.011 | T3: =G3/$G$57 -> 16278.26 | U3: =H3/$H$57 -> 16789.969 | V3: =I3/$I$57 -> 16733.844 | W3: =J3/$J$57 -> 16309.73 | X3: =K3/$K$57 -> 16728.973 | Y3: =L3/$L$57 -> 16073.292 | Z3: =M3/$M$57 -> 16827.726 | AA3: =SUM(O3:Z3) -> 192467.44
A4: Aurivo NI | B4: 651.09342 | C4: 588.08438 | D4: 651.09342 | E4: 630.09041 | F4: 651.09342 | G4: 630.09041 | H4: 651.09342 | I4: 651.09342 | J4: 630.09041 | K4: 651.09342 | L4: 630.09041 | M4: 651.09342 | N4: =SUM(B4:M4) -> 7666.1 | O4: =B4/$B$57 -> 673.64016 | P4: =C4/$C$57 -> 612.24989 | Q4: =D4/$D$57 -> 702.13135 | R4: =E4/$E$57 -> 707.83155 | S4: =F4/$F$57 -> 734.31313 | T4: =G4/$G$57 -> 725.85208 | U4: =H4/$H$57 -> 760.88983 | V4: =I4/$I$57 -> 758.34635 | W4: =J4/$J$57 -> 739.12633 | X4: =K4/$K$57 -> 758.1256 | Y4: =L4/$L$57 -> 728.41138 | Z4: =M4/$M$57 -> 762.60093 | AA4: =SUM(O4:Z4) -> 8663.5186
A5: BallyJamesDuff | B5: 1013.6315 | C5: 915.53812 | D5: 1013.6315 | E5: 980.9337 | F5: 1013.6315 | G5: 974.28 | H5: 997.10489 | I5: 997.10489 | J5: 964.94022 | K5: 997.10489 | L5: =964.940217391304-0.5 -> 964.44022 | M5: 997.10489 | N5: =SUM(B5:M5) -> 11829.446 | O5: =B5/$B$57 -> 1048.7326 | P5: =C5/$C$57 -> 953.15932 | Q5: =D5/$D$57 -> 1093.0881 | R5: =E5/$E$57 -> 1101.9622 | S5: =F5/$F$57 -> 1143.1891 | T5: =G5/$G$57 -> 1122.3519 | U5: =H5/$H$57 -> 1165.2505 | V5: =I5/$I$57 -> 1161.3554 | W5: =J5/$J$57 -> 1131.9212 | X5: =K5/$K$57 -> 1161.0173 | Y5: =L5/$L$57 -> 1114.934 | Z5: =M5/$M$57 -> 1167.871 | AA5: =SUM(O5:Z5) -> 13364.833
A6: Bandon Co-Op | B6: 8374.109 | C6: 7563.7113 | D6: 8374.109 | E6: 8103.9764 | F6: 8374.109 | G6: 8103.9764 | H6: 8374.109 | I6: 8374.109 | J6: 8103.9764 | K6: 8374.109 | L6: 8103.9764 | M6: 8374.109 | N6: =SUM(B6:M6) -> 98598.38 | O6: =B6/$B$57 -> 8664.0963 | P6: =C6/$C$57 -> 7874.5186 | Q6: =D6/$D$57 -> 9030.5389 | R6: =E6/$E$57 -> 9103.8526 | S6: =F6/$F$57 -> 9444.4483 | T6: =G6/$G$57 -> 9335.6255 | U6: =H6/$H$57 -> 9786.2674 | V6: =I6/$I$57 -> 9753.5541 | W6: =J6/$J$57 -> 9506.3537 | X6: =K6/$K$57 -> 9750.7149 | Y6: =L6/$L$57 -> 9368.5423 | Z6: =M6/$M$57 -> 9808.2749 | AA6: =SUM(O6:Z6) -> 111426.79
A7: Bandon Vale Cheese | B7: 1225.1744 | C7: 1106.6091 | D7: 1225.1744 | E7: 1185.6526 | F7: 1225.1744 | G7: 1185.6526 | H7: 1225.1744 | I7: 1225.1744 | J7: 1185.6526 | K7: 1225.1744 | L7: 1185.6526 | M7: 1225.1744 | N7: =SUM(B7:M7) -> 14425.44 | O7: =B7/$B$57 -> 1267.601 | P7: =C7/$C$57 -> 1152.0818 | Q7: =D7/$D$57 -> 1321.2134 | R7: =E7/$E$57 -> 1331.9395 | S7: =F7/$F$57 -> 1381.7704 | T7: =G7/$G$57 -> 1365.8491 | U7: =H7/$H$57 -> 1431.7802 | V7: =I7/$I$57 -> 1426.9941 | W7: =J7/$J$57 -> 1390.8275 | X7: =K7/$K$57 -> 1426.5787 | Y7: =L7/$L$57 -> 1370.665 | Z7: =M7/$M$57 -> 1435.0001 | AA7: =SUM(O7:Z7) -> 16302.301
A8: Barryroe Co-Op | B8: 6234.314 | C8: 5630.9933 | D8: 6234.314 | E8: 6033.2071 | F8: 6234.314 | G8: 6033.2071 | H8: 6234.314 | I8: 6234.314 | J8: 6033.2071 | K8: 6234.314 | L8: 6033.2071 | M8: 6234.314 | N8: =SUM(B8:M8) -> 73404.02 | O8: =B8/$B$57 -> 6450.2023 | P8: =C8/$C$57 -> 5862.3815 | Q8: =D8/$D$57 -> 6723.0096 | R8: =E8/$E$57 -> 6777.5898 | S8: =F8/$F$57 -> 7031.1548 | T8: =G8/$G$57 -> 6950.139 | U8: =H8/$H$57 -> 7285.6305 | V8: =I8/$I$57 -> 7261.2763 | W8: =J8/$J$57 -> 7077.2418 | X8: =K8/$K$57 -> 7259.1626 | Y8: =L8/$L$57 -> 6974.6447 | Z8: =M8/$M$57 -> 7302.0146 | AA8: =SUM(O8:Z8) -> 82954.448
A9: Brett Brothers | B9: 4014.2248 | C9: 3664.1743 | D9: 4056.7644 | E9: 3925.9011 | F9: 4124.247 | G9: 3991.2068 | H9: 4124.247 | I9: 4124.247 | J9: 3991.2068 | K9: 4124.247 | L9: 3991.2068 | M9: 4124.247 | N9: =SUM(B9:M9) -> 48255.92 | O9: =B9/$B$57 -> 4153.2335 | P9: =C9/$C$57 -> 3814.7422 | Q9: =D9/$D$57 -> 4374.7662 | R9: =E9/$E$57 -> 4410.2824 | S9: =F9/$F$57 -> 4651.3889 | T9: =G9/$G$57 -> 4597.7937 | U9: =H9/$H$57 -> 4819.7347 | V9: =I9/$I$57 -> 4803.6235 | W9: =J9/$J$57 -> 4681.8773 | X9: =K9/$K$57 -> 4802.2252 | Y9: =L9/$L$57 -> 4614.0052 | Z9: =M9/$M$57 -> 4830.5735 | AA9: =SUM(O9:Z9) -> 54554.246
A10: Callan Co-Op | B10: 1772.6063 | C10: 1601.0638 | D10: 1772.6063 | E10: 2533.6073 | F10: 2753.0273 | G10: 2664.22 | H10: 2753.0273 | I10: 2753.0273 | J10: 2664.22 | K10: 2753.0273 | L10: 2664.22 | M10: 2828.0273 | N10: =SUM(B10:M10) -> 29512.68 | O10: =B10/$B$57 -> 1833.99 | P10: =C10/$C$57 -> 1666.8545 | Q10: =D10/$D$57 -> 1911.5574 | R10: =E10/$E$57 -> 2846.2061 | S10: =F10/$F$57 -> 3104.9063 | T10: =G10/$G$57 -> 3069.1303 | U10: =H10/$H$57 -> 3217.2809 | V10: =I10/$I$57 -> 3206.5263 | W10: =J10/$J$57 -> 3125.258 | X10: =K10/$K$57 -> 3205.5929 | Y10: =L10/$L$57 -> 3079.9519 | Z10: =M10/$M$57 -> 3312.3607 | AA10: =SUM(O10:Z10) -> 33579.615
A11: Carbery | B11: 1478.6066 | C11: 1335.5156 | D11: 1478.6066 | E11: 1430.9096 | F11: 1478.6066 | G11: 1430.9096 | H11: 1478.6066 | I11: 1478.6066 | J11: 1430.9096 | K11: 1478.6066 | L11: 1430.9096 | M11: 1478.6066 | N11: =SUM(B11:M11) -> 17409.4 | O11: =B11/$B$57 -> 1529.8093 | P11: =C11/$C$57 -> 1390.3945 | Q11: =D11/$D$57 -> 1594.5116 | R11: =E11/$E$57 -> 1607.4565 | S11: =F11/$F$57 -> 1667.5951 | T11: =G11/$G$57 -> 1648.3804 | U11: =H11/$H$57 -> 1727.9497 | V11: =I11/$I$57 -> 1722.1736 | W11: =J11/$J$57 -> 1678.5257 | X11: =K11/$K$57 -> 1721.6723 | Y11: =L11/$L$57 -> 1654.1925 | Z11: =M11/$M$57 -> 1731.8356 | AA11: =SUM(O11:Z11) -> 19674.497
A12: Centenary Thurles Co-Op | B12: 3213.4771 | C12: 2902.4955 | D12: 3213.4771 | E12: 3109.8166 | F12: 3213.4771 | G12: 3109.8166 | H12: 3161.0835 | I12: 3161.0835 | J12: 3059.113 | K12: 3161.0835 | L12: 3059.113 | M12: 3161.0835 | N12: =SUM(B12:M12) -> 37525.12 | O12: =B12/$B$57 -> 3324.7567 | P12: =C12/$C$57 -> 3021.7645 | Q12: =D12/$D$57 -> 3465.3753 | R12: =E12/$E$57 -> 3493.5086 | S12: =F12/$F$57 -> 3624.2087 | T12: =G12/$G$57 -> 3582.4491 | U12: =H12/$H$57 -> 3694.1492 | V12: =I12/$I$57 -> 3681.8005 | W12: =J12/$J$57 -> 3588.4866 | X12: =K12/$K$57 -> 3680.7288 | Y12: =L12/$L$57 -> 3536.4651 | Z12: =M12/$M$57 -> 3702.4567 | AA12: =SUM(O12:Z12) -> 42396.15
A13: Centenary Thurles Feed & Grain | B13: 1515.3999 | C13: 1368.7483 | D13: 1515.3999 | E13: 1466.516 | F13: 1515.3999 | G13: 1466.516 | H13: 1490.6923 | I13: 1490.6923 | J13: 1442.6054 | K13: 1490.6923 | L13: 1442.6054 | M13: 1490.6923 | N13: =SUM(B13:M13) -> 17695.96 | O13: =B13/$B$57 -> 1567.8767 | P13: =C13/$C$57 -> 1424.9928 | Q13: =D13/$D$57 -> 1634.1891 | R13: =E13/$E$57 -> 1647.4561 | S13: =F13/$F$57 -> 1709.0912 | T13: =G13/$G$57 -> 1689.3983 | U13: =H13/$H$57 -> 1742.0735 | V13: =I13/$I$57 -> 1736.2501 | W13: =J13/$J$57 -> 1692.2455 | X13: =K13/$K$57 -> 1735.7447 | Y13: =L13/$L$57 -> 1667.7134 | Z13: =M13/$M$57 -> 1745.9911 | AA13: =SUM(O13:Z13) -> 19993.023
A14: Centenary Thurles Fresh Milk | B14: 858.17249 | C14: 775.12354 | D14: 858.17249 | E14: 830.4895 | F14: 858.17249 | G14: 830.4895 | H14: 844.18054 | I14: 844.18054 | J14: 816.94891 | K14: 844.18054 | L14: 816.94891 | M14: 844.18054 | N14: =SUM(B14:M14) -> 10021.24 | O14: =B14/$B$57 -> 887.89017 | P14: =C14/$C$57 -> 806.97483 | Q14: =D14/$D$57 -> 925.44293 | R14: =E14/$E$57 -> 932.95607 | S14: =F14/$F$57 -> 967.86007 | T14: =G14/$G$57 -> 956.70799 | U14: =H14/$H$57 -> 986.53797 | V14: =I14/$I$57 -> 983.24021 | W14: =J14/$J$57 -> 958.32033 | X14: =K14/$K$57 -> 982.95399 | Y14: =L14/$L$57 -> 944.42777 | Z14: =M14/$M$57 -> 988.75652 | AA14: =SUM(O14:Z14) -> 11322.069
A15: Centenary Thurles Stores | B15: 3526.5788 | C15: 3185.297 | D15: 3526.5788 | E15: 3412.8182 | F15: 3526.5788 | G15: 3412.8182 | H15: 3469.0803 | I15: 3469.0803 | J15: 3357.1745 | K15: 3469.0803 | L15: 3357.1745 | M15: 3469.0803 | N15: =SUM(B15:M15) -> 41181.34 | O15: =B15/$B$57 -> 3648.7009 | P15: =C15/$C$57 -> 3316.1869 | Q15: =D15/$D$57 -> 3803.0204 | R15: =E15/$E$57 -> 3833.8949 | S15: =F15/$F$57 -> 3977.3296 | T15: =G15/$G$57 -> 3931.5012 | U15: =H15/$H$57 -> 4054.0847 | V15: =I15/$I$57 -> 4040.5328 | W15: =J15/$J$57 -> 3938.1269 | X15: =K15/$K$57 -> 4039.3566 | Y15: =L15/$L$57 -> 3881.0368 | Z15: =M15/$M$57 -> 4063.2016 | AA15: =SUM(O15:Z15) -> 46526.973
A16: Dan O'Connor | B16: 3253.9893 | C16: 2939.0871 | D16: 3253.9893 | E16: 3149.0219 | F16: 3253.9893 | G16: 3149.0219 | H16: 3253.9893 | I16: 3253.9893 | J16: 3149.0219 | K16: 3253.9893 | L16: 3149.0219 | M16: 3253.9893 | N16: =SUM(B16:M16) -> 38313.1 | O16: =B16/$B$57 -> 3366.6718 | P16: =C16/$C$57 -> 3059.8598 | Q16: =D16/$D$57 -> 3509.0631 | R16: =E16/$E$57 -> 3537.5512 | S16: =F16/$F$57 -> 3669.899 | T16: =G16/$G$57 -> 3627.6129 | U16: =H16/$H$57 -> 3802.7221 | V16: =I16/$I$57 -> 3790.0105 | W16: =J16/$J$57 -> 3693.954 | X16: =K16/$K$57 -> 3788.9072 | Y16: =L16/$L$57 -> 3640.4036 | Z16: =M16/$M$57 -> 3811.2738 | AA16: =SUM(O16:Z16) -> 43297.929
A17: Denis Brinicombe | B17: 2547.7252 | C17: 2301.1712 | D17: 2547.7252 | E17: 2589.4558 | F17: 2675.771 | G17: 2589.4558 | H17: 2675.771 | I17: 2675.771 | J17: 2589.4558 | K17: 2675.771 | L17: 2589.4558 | M17: 2675.771 | N17: =SUM(B17:M17) -> 31133.3 | O17: =B17/$B$57 -> 2635.9505 | P17: =C17/$C$57 -> 2395.7307 | Q17: =D17/$D$57 -> 2747.4364 | R17: =E17/$E$57 -> 2908.9453 | S17: =F17/$F$57 -> 3017.7755 | T17: =G17/$G$57 -> 2983.0035 | U17: =H17/$H$57 -> 3126.9966 | V17: =I17/$I$57 -> 3116.5438 | W17: =J17/$J$57 -> 3037.5561 | X17: =K17/$K$57 -> 3115.6366 | Y17: =L17/$L$57 -> 2993.5213 | Z17: =M17/$M$57 -> 3134.0287 | AA17: =SUM(O17:Z17) -> 35213.125
... A21: ECV | B21: 2557.2868 | C21: 2309.8075 | D21: 2557.2868 | E21: 2474.7937 | F21: 2557.2868 | G21: 2597.4573 | H21: 2684.0392 | I21: 2696.7026 | J21: 2609.7122 | K21: 2696.7026 | L21: 2609.7122 | M21: 2696.7026 | N21: =SUM(B21:M21) -> 31047.49 | O21: =B21/$B$57 -> 2645.8432 | P21: =C21/$C$57 -> 2404.7218 | Q21: =D21/$D$57 -> 2757.7475 | R21: =E21/$E$57 -> 2780.136 | S21: =F21/$F$57 -> 2884.1472 | T21: =G21/$G$57 -> 2992.221 | U21: =H21/$H$57 -> 3136.6591 | V21: =I21/$I$57 -> 3140.9233 | W21: =J21/$J$57 -> 3061.3177 | X21: =K21/$K$57 -> 3140.009 | Y21: =L21/$L$57 -> 3016.9385 | Z21: =M21/$M$57 -> 3158.545 | AA21: =SUM(O21:Z21) -> 35119.209
A22: Hopkins | B22: 1506.8809 | C22: 1361.0537 | D22: 1506.8809 | E22: 1458.2718 | F22: 1506.8809 | G22: 1458.2718 | H22: 1482.3122 | I22: 1482.3122 | J22: 1434.4957 | K22: 1482.3122 | L22: 1434.4957 | M22: =1482.31217391304-0.83 -> 1481.4822 | N22: =SUM(B22:M22) -> 17595.65 | O22: =B22/$B$57 -> 1559.0627 | P22: =C22/$C$57 -> 1416.982 | Q22: =D22/$D$57 -> 1625.0023 | R22: =E22/$E$57 -> 1638.1948 | S22: =F22/$F$57 -> 1699.4833 | T22: =G22/$G$57 -> 1679.9012 | U22: =H22/$H$57 -> 1732.2802 | V22: =I22/$I$57 -> 1726.4896 | W22: =J22/$J$57 -> 1682.7323 | X22: =K22/$K$57 -> 1725.987 | Y22: =L22/$L$57 -> 1658.3381 | Z22: =M22/$M$57 -> 1735.2037 | AA22: =SUM(O22:Z22) -> 19879.657
A23: ICMSA | B23: 275.82271 | C23: 249.13019 | D23: 275.82271 | E23: 266.92521 | F23: 275.82271 | G23: 266.92521 | H23: 275.82271 | I23: 275.82271 | J23: 266.92521 | K23: 275.82271 | L23: 266.92521 | M23: 275.82271 | N23: =SUM(B23:M23) -> 3247.59 | O23: =B23/$B$57 -> 285.37419 | P23: =C23/$C$57 -> 259.36742 | Q23: =D23/$D$57 -> 297.44391 | R23: =E23/$E$57 -> 299.85868 | S23: =F23/$F$57 -> 311.07708 | T23: =G23/$G$57 -> 307.49272 | U23: =H23/$H$57 -> 322.33576 | V23: =I23/$I$57 -> 321.25827 | W23: =J23/$J$57 -> 313.11609 | X23: =K23/$K$57 -> 321.16475 | Y23: =L23/$L$57 -> 308.57692 | Z23: =M23/$M$57 -> 323.06064 | AA23: =SUM(O23:Z23) -> 3670.1264
A24: Irish International Traders | B24: 899.83148 | C24: 812.75101 | D24: 899.83148 | E24: 870.80466 | F24: 899.83148 | G24: 870.80466 | H24: 899.83148 | I24: 899.83148 | J24: 870.80466 | K24: 899.83148 | L24: 870.80466 | M24: 899.83148 | N24: =SUM(B24:M24) -> 10594.79 | O24: =B24/$B$57 -> 930.99177 | P24: =C24/$C$57 -> 846.14849 | Q24: =D24/$D$57 -> 970.36749 | R24: =E24/$E$57 -> 978.24534 | S24: =F24/$F$57 -> 1014.8437 | T24: =G24/$G$57 -> 1003.1503 | U24: =H24/$H$57 -> 1051.5735 | V24: =I24/$I$57 -> 1048.0584 | W24: =J24/$J$57 -> 1021.4957 | X24: =K24/$K$57 -> 1047.7533 | Y24: =L24/$L$57 -> 1006.6873 | Z24: =M24/$M$57 -> 1053.9383 | AA24: =SUM(O24:Z24) -> 11973.254
A25: J.McKenna | B25: 2978.6247 | C25: =2690.37-39.09 -> 2651.28 | D25: 2978.6247 | E25: 2850.8637 | F25: 2945.8925 | G25: 2850.8637 | H25: =2913.87195652174-36.57 -> 2877.302 | I25: 2913.872 | J25: 2819.8761 | K25: 2913.872 | L25: 2819.8761 | M25: =2913.87195652174-36.57 -> 2877.302 | N25: =SUM(B25:M25) -> 34478.249 | O25: =B25/$B$57 -> 3081.7716 | P25: =C25/$C$57 -> 2760.2261 | Q25: =D25/$D$57 -> 3212.1132 | R25: =E25/$E$57 -> 3202.6059 | S25: =F25/$F$57 -> 3322.4227 | T25: =G25/$G$57 -> 3284.1404 | U25: =H25/$H$57 -> 3362.5125 | V25: =I25/$I$57 -> 3393.8665 | W25: =J25/$J$57 -> 3307.8501 | X25: =K25/$K$57 -> 3392.8786 | Y25: =L25/$L$57 -> 3259.897 | Z25: =M25/$M$57 -> 3370.0742 | AA25: =SUM(O25:Z25) -> 38950.359
A26: John McCarthy | B26: 1818.9501 | C26: =1642.92263013699-0.54 -> 1642.3826 | D26: 1818.9501 | E26: 1723.7 | F26: 1818.9501 | G26: 1760.2742 | H26: 1818.9501 | I26: 1818.9501 | J26: 1760.2742 | K26: 1818.9501 | L26: 1760.2742 | M26: 1818.9501 | N26: =SUM(B26:M26) -> 21379.556 | O26: =B26/$B$57 -> 1881.9385 | P26: =C26/$C$57 -> 1709.8712 | Q26: =D26/$D$57 -> 1961.534 | R26: =E26/$E$57 -> 1936.3717 | S26: =F26/$F$57 -> 2051.4397 | T26: =G26/$G$57 -> 2027.8022 | U26: =H26/$H$57 -> 2125.6866 | V26: =I26/$I$57 -> 2118.581 | W26: =J26/$J$57 -> 2064.8863 | X26: =K26/$K$57 -> 2117.9642 | Y26: =L26/$L$57 -> 2034.9521 | Z26: =M26/$M$57 -> 2130.4669 | AA26: =SUM(O26:Z26) -> 24161.494
A27: Kelliher Mills | B27: 383.94189 | C27: 346.78622 | D27: 383.94189 | E27: 367.47363 | F27: 379.72275 | G27: 367.47363 | H27: 375.59533 | I27: 375.59533 | J27: =363.479347826087-0.08 -> 363.39935 | K27: 375.59533 | L27: 363.47935 | M27: 375.59533 | N27: =SUM(B27:M27) -> 4458.6 | O27: =B27/$B$57 -> 397.23743 | P27: =C27/$C$57 -> 361.03633 | Q27: =D27/$D$57 -> 414.03834 | R27: =E27/$E$57 -> 412.81286 | S27: =F27/$F$57 -> 428.25713 | T27: =G27/$G$57 -> 423.32257 | U27: =H27/$H$57 -> 438.93342 | V27: =I27/$I$57 -> 437.46617 | W27: =J27/$J$57 -> 426.2849 | X27: =K27/$K$57 -> 437.33882 | Y27: =L27/$L$57 -> 420.19762 | Z27: =M27/$M$57 -> 439.9205 | AA27: =SUM(O27:Z27) -> 5036.8461
A28: Kerry | B28: 3778.81 | C28: 3413.1187 | D28: 3778.81 | E28: 3656.9129 | F28: 3778.81 | G28: 3656.9129 | H28: 3778.81 | I28: 3778.81 | J28: 3656.9129 | K28: 3778.81 | L28: 3656.9129 | M28: 3778.81 | N28: =SUM(B28:M28) -> 44492.44 | O28: =B28/$B$57 -> 3909.6665 | P28: =C28/$C$57 -> 3553.3702 | Q28: =D28/$D$57 -> 4075.0234 | R28: =E28/$E$57 -> 4108.1062 | S28: =F28/$F$57 -> 4261.7997 | T28: =G28/$G$57 -> 4212.6935 | U28: =H28/$H$57 -> 4416.0453 | V28: =I28/$I$57 -> 4401.2835 | W28: =J28/$J$57 -> 4289.7345 | X28: =K28/$K$57 -> 4400.0023 | Y28: =L28/$L$57 -> 4227.5472 | Z28: =M28/$M$57 -> 4425.9762 | AA28: =SUM(O28:Z28) -> 50281.249
A29: Kiernan Milling | J29: 3012.2951 | K29: 3112.7049 | L29: 3012.2951 | M29: 3162.7049 | N29: =SUM(B29:M29) -> 12300 | O29: =B29/$B$57 -> 0 | P29: =C29/$C$57 -> 0 | Q29: =D29/$D$57 -> 0 | R29: =E29/$E$57 -> 0 | S29: =F29/$F$57 -> 0 | T29: =G29/$G$57 -> 0 | U29: =H29/$H$57 -> 0 | V29: =I29/$I$57 -> 0 | W29: =J29/$J$57 -> 3533.5669 | X29: =K29/$K$57 -> 3624.3973 | Y29: =L29/$L$57 -> 3482.3415 | Z29: =M29/$M$57 -> 3704.3558 | AA29: =SUM(O29:Z29) -> 14344.662
A30: Lacpatrick Dairies | B30: 2985.2587 | C30: 2696.3627 | D30: 2985.2587 | E30: 3289.0154 | F30: 3398.6492 | G30: 3289.0154 | H30: 3361.7074 | I30: 3361.7074 | J30: 3253.2652 | K30: 3361.7074 | L30: 3253.2652 | M30: 3361.7074 | N30: =SUM(B30:M30) -> 38596.92 | O30: =B30/$B$57 -> 3088.6353 | P30: =C30/$C$57 -> 2807.1613 | Q30: =D30/$D$57 -> 3219.2672 | R30: =E30/$E$57 -> 3694.8172 | S30: =F30/$F$57 -> 3833.0486 | T30: =G30/$G$57 -> 3788.8827 | U30: =H30/$H$57 -> 3928.6051 | V30: =I30/$I$57 -> 3915.4727 | W30: =J30/$J$57 -> 3816.2364 | X30: =K30/$K$57 -> 3914.3329 | Y30: =L30/$L$57 -> 3760.9133 | Z30: =M30/$M$57 -> 3937.4398 | AA30: =SUM(O30:Z30) -> 43704.813
A31: Lakeland Dairies | B31: 4918.3071 | C31: 4442.3419 | D31: 4918.3071 | E31: 4759.6521 | F31: 4918.3071 | G31: 4759.6521 | H31: 4918.3071 | I31: 4918.3071 | J31: 4759.6521 | K31: 4918.3071 | L31: 4759.6521 | M31: 4918.3071 | N31: =SUM(B31:M31) -> 57909.1 | O31: =B31/$B$57 -> 5088.6233 | P31: =C31/$C$57 -> 4624.8862 | Q31: =D31/$D$57 -> 5303.8435 | R31: =E31/$E$57 -> 5346.9023 | S31: =F31/$F$57 -> 5546.9421 | T31: =G31/$G$57 -> 5483.0279 | U31: =H31/$H$57 -> 5747.7003 | V31: =I31/$I$57 -> 5728.487 | W31: =J31/$J$57 -> 5583.3006 | X31: =K31/$K$57 -> 5726.8195 | Y31: =L31/$L$57 -> 5502.3607 | Z31: =M31/$M$57 -> 5760.6258 | AA31: =SUM(O31:Z31) -> 65443.519
A32: Lacpatrick Dairies NI | B32: 451.15333 | C32: 407.49333 | D32: 451.15333 | M32: 0 | N32: =SUM(B32:M32) -> 1309.8 | O32: =B32/$B$57 -> 466.77634 | P32: =C32/$C$57 -> 424.23801 | Q32: =D32/$D$57 -> 486.51835 | R32: =E32/$E$57 -> 0 | S32: =F32/$F$57 -> 0 | T32: =G32/$G$57 -> 0 | U32: =H32/$H$57 -> 0 | V32: =I32/$I$57 -> 0 | W32: =J32/$J$57 -> 0 | X32: =K32/$K$57 -> 0 | Y32: =L32/$L$57 -> 0 | Z32: =M32/$M$57 -> 0 | AA32: =SUM(O32:Z32) -> 1377.5327
A33: Lakeland Dairies NI | B33: 4599.6968 | C33: 4154.5648 | D33: 4599.6968 | E33: 4451.3195 | F33: 4599.6968 | G33: 4451.3195 | H33: 4599.6968 | I33: 4599.6968 | J33: 4451.3195 | K33: 4599.6968 | L33: 4451.3195 | M33: 4599.6968 | N33: =SUM(B33:M33) -> 54157.72 | O33: =B33/$B$57 -> 4758.9798 | P33: =C33/$C$57 -> 4325.2838 | Q33: =D33/$D$57 -> 4960.2579 | R33: =E33/$E$57 -> 5000.5274 | S33: =F33/$F$57 -> 5187.6084 | T33: =G33/$G$57 -> 5127.8347 | U33: =H33/$H$57 -> 5375.3614 | V33: =I33/$I$57 -> 5357.3928 | W33: =J33/$J$57 -> 5221.6116 | X33: =K33/$K$57 -> 5355.8333 | Y33: =L33/$L$57 -> 5145.9151 | Z33: =M33/$M$57 -> 5387.4497 | AA33: =SUM(O33:Z33) -> 61204.056
A34: Lee Strand | B34: 3549.9391 | C34: 3206.3966 | D34: 3549.9391 | E34: 3435.4249 | F34: 3549.9391 | G34: 3435.4249 | H34: 3549.9391 | I34: 3549.9391 | J34: 3435.4249 | K34: 3549.9391 | L34: 3435.4249 | M34: 3549.9391 | N34: =SUM(B34:M34) -> 41797.67 | O34: =B34/$B$57 -> 3672.8701 | P34: =C34/$C$57 -> 3338.1535 | Q34: =D34/$D$57 -> 3828.2118 | R34: =E34/$E$57 -> 3859.2908 | S34: =F34/$F$57 -> 4003.6757 | T34: =G34/$G$57 -> 3957.5437 | U34: =H34/$H$57 -> 4148.5791 | V34: =I34/$I$57 -> 4134.7113 | W34: =J34/$J$57 -> 4029.9185 | X34: =K34/$K$57 -> 4133.5077 | Y34: =L34/$L$57 -> 3971.4977 | Z34: =M34/$M$57 -> 4157.9085 | AA34: =SUM(O34:Z34) -> 47235.868
A35: Lisavaird | B35: 7861.6493 | C35: 7100.8445 | D35: 7976.8862 | E35: 7755.5673 | F35: 8014.0862 | G35: 7791.5491 | H35: 8051.2674 | I35: 8051.2674 | J35: 7791.5491 | K35: 8051.2674 | L35: 7791.5491 | M35: 8051.2674 | N35: =SUM(B35:M35) -> 94288.75 | O35: =B35/$B$57 -> 8133.8906 | P35: =C35/$C$57 -> 7392.6317 | Q35: =D35/$D$57 -> 8602.1785 | R35: =E35/$E$57 -> 8712.4564 | S35: =F35/$F$57 -> 9038.4091 | T35: =G35/$G$57 -> 8975.7152 | U35: =H35/$H$57 -> 9408.9837 | V35: =I35/$I$57 -> 9377.5317 | W35: =J35/$J$57 -> 9139.8614 | X35: =K35/$K$57 -> 9374.8019 | Y35: =L35/$L$57 -> 9007.3629 | Z35: =M35/$M$57 -> 9430.1428 | AA35: =SUM(O35:Z35) -> 106593.97
A36: M.D O'Shea | B36: 8301.1283 | C36: =7497.79-0.06 -> 7497.73 | D36: 8301.1283 | E36: 7945.0714 | F36: 8209.9071 | G36: 8043.2023 | H36: 8425.9296 | I36: 8425.9296 | J36: =8154.12540633889-0.86 -> 8153.2654 | K36: =8510.16871698496-0.06 -> 8510.1087 | L36: 8235.6471 | M36: 8510.1687 | N36: =SUM(B36:M36) -> 98559.217 | O36: =B36/$B$57 -> 8588.5884 | P36: =C36/$C$57 -> 7805.826 | Q36: =D36/$D$57 -> 8951.8374 | R36: =E36/$E$57 -> 8925.3417 | S36: =F36/$F$57 -> 9259.259 | T36: =G36/$G$57 -> 9265.6148 | U36: =H36/$H$57 -> 9846.8267 | V36: =I36/$I$57 -> 9813.911 | W36: =J36/$J$57 -> 9564.1721 | X36: =K36/$K$57 -> 9909.0714 | Y36: =L36/$L$57 -> 9520.7592 | Z36: =M36/$M$57 -> 9967.6365 | AA36: =SUM(O36:Z36) -> 111418.84
A37: McDonnell | B37: 3467.773 | C37: 3132.182 | D37: 3467.773 | E37: 3355.9093 | F37: 3467.773 | G37: 3355.9093 | H37: 3467.773 | I37: 3467.773 | J37: 3355.9093 | K37: 3467.773 | L37: 3355.9093 | M37: 3467.773 | N37: =SUM(B37:M37) -> 40830.23 | O37: =B37/$B$57 -> 3587.8586 | P37: =C37/$C$57 -> 3260.8893 | Q37: =D37/$D$57 -> 3739.6048 | R37: =E37/$E$57 -> 3769.9645 | S37: =F37/$F$57 -> 3911.0074 | T37: =G37/$G$57 -> 3865.9432 | U37: =H37/$H$57 -> 4052.5569 | V37: =I37/$I$57 -> 4039.0102 | W37: =J37/$J$57 -> 3936.6429 | X37: =K37/$K$57 -> 4037.8344 | Y37: =L37/$L$57 -> 3879.5742 | Z37: =M37/$M$57 -> 4061.6704 | AA37: =SUM(O37:Z37) -> 46142.557
A38: McDonogh | B38: 1995.1184 | C38: 1802.0424 | D38: 1995.1184 | E38: 1930.7597 | F38: 1995.1184 | G38: 1930.7597 | H38: 1995.1184 | I38: 1995.1184 | J38: 1971.7442 | K38: 2037.469 | L38: 1971.7442 | M38: 2037.469 | N38: =SUM(B38:M38) -> 23657.58 | O38: =B38/$B$57 -> 2064.2074 | P38: =C38/$C$57 -> 1876.0918 | Q38: =D38/$D$57 -> 2151.5118 | R38: =E38/$E$57 -> 2168.9787 | S38: =F38/$F$57 -> 2250.1251 | T38: =G38/$G$57 -> 2224.1982 | U38: =H38/$H$57 -> 2331.5629 | V38: =I38/$I$57 -> 2323.769 | W38: =J38/$J$57 -> 2312.9506 | X38: =K38/$K$57 -> 2372.4051 | Y38: =L38/$L$57 -> 2279.4203 | Z38: =M38/$M$57 -> 2386.4098 | AA38: =SUM(O38:Z38) -> 26741.631
A39: Morris DIY | B39: 3763.6946 | C39: 3399.4661 | D39: 3763.6946 | E39: 3642.2851 | F39: 3763.6946 | G39: 3642.2851 | H39: 3702.33 | I39: 3702.33 | J39: 3582.9 | K39: 3702.33 | L39: 3582.9 | M39: 3702.33 | N39: =SUM(B39:M39) -> 43950.24 | O39: =B39/$B$57 -> 3894.0277 | P39: =C39/$C$57 -> 3539.1566 | Q39: =D39/$D$57 -> 4058.7232 | R39: =E39/$E$57 -> 4091.6736 | S39: =F39/$F$57 -> 4244.7524 | T39: =G39/$G$57 -> 4195.8426 | U39: =H39/$H$57 -> 4326.6682 | V39: =I39/$I$57 -> 4312.2052 | W39: =J39/$J$57 -> 4202.9139 | X39: =K39/$K$57 -> 4310.9499 | Y39: =L39/$L$57 -> 4141.9852 | Z39: =M39/$M$57 -> 4336.3981 | AA39: =SUM(O39:Z39) -> 49655.296
A40: North Cork | B40: 6704.99 | C40: 6056.12 | D40: 6704.99 | E40: 6488.7 | F40: 6704.99 | G40: 6488.7 | H40: 6595.6695 | I40: 6595.6695 | J40: 6382.906 | K40: 6595.6695 | L40: 6382.906 | M40: 6595.6695 | N40: =SUM(B40:M40) -> 78296.98 | O40: =B40/$B$57 -> 6937.1773 | P40: =C40/$C$57 -> 6304.9775 | Q40: =D40/$D$57 -> 7230.5809 | R40: =E40/$E$57 -> 7289.2818 | S40: =F40/$F$57 -> 7561.9904 | T40: =G40/$G$57 -> 7474.858 | U40: =H40/$H$57 -> 7707.9228 | V40: =I40/$I$57 -> 7682.157 | W40: =J40/$J$57 -> 7487.4554 | X40: =K40/$K$57 -> 7679.9207 | Y40: =L40/$L$57 -> 7378.9114 | Z40: =M40/$M$57 -> 7725.2565 | AA40: =SUM(O40:Z40) -> 88460.49
A41: Organic Herd | B41: 1815.4212 | C41: 1639.7352 | D41: 1815.4212 | E41: 1756.8592 | F41: 1815.4212 | G41: 1756.8592 | H41: 1815.4212 | I41: 1815.4212 | J41: 1756.8592 | K41: 1815.4212 | L41: 1756.8592 | M41: 1815.4212 | N41: =SUM(B41:M41) -> 21375.12 | O41: =B41/$B$57 -> 1878.2874 | P41: =C41/$C$57 -> 1707.1151 | Q41: =D41/$D$57 -> 1957.7284 | R41: =E41/$E$57 -> 1973.6221 | S41: =F41/$F$57 -> 2047.4598 | T41: =G41/$G$57 -> 2023.8681 | U41: =H41/$H$57 -> 2121.5626 | V41: =I41/$I$57 -> 2114.4707 | W41: =J41/$J$57 -> 2060.8802 | X41: =K41/$K$57 -> 2113.8552 | Y41: =L41/$L$57 -> 2031.0041 | Z41: =M41/$M$57 -> 2126.3337 | AA41: =SUM(O41:Z41) -> 24156.188
A42: Peter Curran | B42: 2692.8912 | C42: 2432.2888 | D42: 2692.8912 | E42: 2606.0238 | F42: 2692.8912 | G42: 2606.0238 | H42: 2648.9854 | I42: 2648.9854 | J42: 2563.5342 | K42: 2648.9854 | L42: 2563.5342 | M42: 2648.9854 | N42: =SUM(B42:M42) -> 31446.02 | O42: =B42/$B$57 -> 2786.1434 | P42: =C42/$C$57 -> 2532.2362 | Q42: =D42/$D$57 -> 2903.9816 | R42: =E42/$E$57 -> 2927.5574 | S42: =F42/$F$57 -> 3037.0839 | T42: =G42/$G$57 -> 3002.0894 | U42: =H42/$H$57 -> 3095.694 | V42: =I42/$I$57 -> 3085.3458 | W42: =J42/$J$57 -> 3007.1488 | X42: =K42/$K$57 -> 3084.4477 | Y42: =L42/$L$57 -> 2963.5549 | Z42: =M42/$M$57 -> 3102.6557 | AA42: =SUM(O42:Z42) -> 35527.939
A43: Richard Boyle | B43: 5531.9329 | C43: 4996.5845 | D43: 5531.9329 | E43: 5353.4834 | F43: 5531.9329 | G43: 5353.4834 | H43: 5441.7383 | I43: 5441.7383 | J43: 5266.1984 | K43: 5441.7383 | L43: 5266.1984 | M43: 5441.7383 | N43: =SUM(B43:M43) -> 64598.7 | O43: =B43/$B$57 -> 5723.4984 | P43: =C43/$C$57 -> 5201.9037 | Q43: =D43/$D$57 -> 5965.5702 | R43: =E43/$E$57 -> 6014.0012 | S43: =F43/$F$57 -> 6238.9986 | T43: =G43/$G$57 -> 6167.1103 | U43: =H43/$H$57 -> 6359.3997 | V43: =I43/$I$57 -> 6338.1417 | W43: =J43/$J$57 -> 6177.5037 | X43: =K43/$K$57 -> 6336.2967 | Y43: =L43/$L$57 -> 6087.9498 | Z43: =M43/$M$57 -> 6373.7009 | AA43: =SUM(O43:Z43) -> 72984.075
...

Sheet Hosting
A1: Customer | B1: January | C1: February | D1: March | E1: April | F1: May | G1: June | H1: July | I1: August | J1: September | K1: October | L1: November | M1: December | N1: Consildated Eur | O1: Jan USD | P1: Feb USD | Q1: March USD | R1: Apr USD | S1: May USD | T1: June USD | U1: July USD | V1: August USD | W1: Sept USD | X1: Oct USD | Y1: Nov USD | Z1: Dec USD | AA1: Consol USD
A2: Arrabawn | B2: 897.49332 | C2: 810.63912 | D2: 897.49332 | E2: 868.54192 | F2: 897.49332 | G2: 868.54192 | H2: 897.49332 | I2: 897.49332 | J2: 868.54192 | K2: 897.49332 | L2: 868.54192 | M2: 897.49332 | N2: =SUM(B2:M2) -> 10567.26 | O2: =B2/$B$44 -> 928.57264 | P2: =C2/$C$44 -> 843.94982 | Q2: =D2/$D$44 -> 967.84604 | R2: =E2/$E$44 -> 975.70342 | S2: =F2/$F$44 -> 1012.2067 | T2: =G2/$G$44 -> 1000.5436 | U2: =H2/$H$44 -> 1048.8411 | V2: =I2/$I$44 -> 1045.3351 | W2: =J2/$J$44 -> 1018.8414 | X2: =K2/$K$44 -> 1045.0308 | Y2: =L2/$L$44 -> 1004.0715 | Z2: =M2/$M$44 -> 1051.1997 | AA2: =SUM(O2:Z2) -> 11942.142 | AD2: 868.97235 | AE2: =AD2/0.95474 -> 910.16648 | AF2: =AE2-Z2 -> -141.03326
A3: BallyJamesDuff | B3: 685.75737 | C3: 619.39375 | D3: 685.75737 | E3: 663.63616 | F3: 685.75737 | G3: 663.63616 | H3: 685.75737 | I3: 685.75737 | J3: 663.63616 | K3: 685.75737 | L3: 663.63616 | M3: 685.75737 | N3: =SUM(B3:M3) -> 8074.24 | O3: =B3/$B$44 -> 709.50448 | P3: =C3/$C$44 -> 644.84582 | Q3: =D3/$D$44 -> 739.51254 | R3: =E3/$E$44 -> 745.51621 | S3: =F3/$F$44 -> 773.40766 | T3: =G3/$G$44 -> 764.49614 | U3: =H3/$H$44 -> 801.39929 | V3: =I3/$I$44 -> 798.7204 | W3: =J3/$J$44 -> 778.47711 | X3: =K3/$K$44 -> 798.48789 | Y3: =L3/$L$44 -> 767.1917 | Z3: =M3/$M$44 -> 803.20149 | AA3: =SUM(O3:Z3) -> 9124.7607 | AD3: 663.96495 | AE3: =AD3/0.95474 -> 695.44059 | AF3: =AE3-Z3 -> -107.76091
A4: Bandon Co-Op | B4: 2593.3632 | C4: 2342.3925 | D4: 2593.3632 | E4: 2509.7063 | F4: 2593.3632 | G4: 2509.7063 | H4: 2593.3632 | I4: 2593.3632 | J4: 2509.7063 | K4: 2593.3632 | L4: 2509.7063 | M4: 2593.3632 | N4: =SUM(B4:M4) -> 30534.76 | O4: =B4/$B$44 -> 2683.1688 | P4: =C4/$C$44 -> 2438.6459 | Q4: =D4/$D$44 -> 2796.6518 | R4: =E4/$E$44 -> 2819.3562 | S4: =F4/$F$44 -> 2924.8347 | T4: =G4/$G$44 -> 2891.1336 | U4: =H4/$H$44 -> 3030.692 | V4: =I4/$I$44 -> 3020.5611 | W4: =J4/$J$44 -> 2944.0061 | X4: =K4/$K$44 -> 3019.6819 | Y4: =L4/$L$44 -> 2901.3275 | Z4: =M4/$M$44 -> 3037.5075 | AA4: =SUM(O4:Z4) -> 34507.567 | AD4: 2510.9492 | AE4: =AD4/0.95474 -> 2629.9822 | AF4: =AE4-Z4 -> -407.52536
A5: Barryroe Co-Op | B5: 2397.2733 | C5: 2165.2791 | D5: 2397.2733 | E5: 2319.9419 | F5: 2397.2733 | G5: 2319.9419 | H5: 2397.2733 | I5: 2397.2733 | J5: 2319.9419 | K5: 2397.2733 | L5: 2319.9419 | M5: 2397.2733 | N5: =SUM(B5:M5) -> 28225.96 | O5: =B5/$B$44 -> 2480.2886 | P5: =C5/$C$44 -> 2254.2546 | Q5: =D5/$D$44 -> 2585.1908 | R5: =E5/$E$44 -> 2606.1785 | S5: =F5/$F$44 -> 2703.6815 | T5: =G5/$G$44 -> 2672.5286 | U5: =H5/$H$44 -> 2801.5348 | V5: =I5/$I$44 -> 2792.1699 | W5: =J5/$J$44 -> 2721.4033 | X5: =K5/$K$44 -> 2791.3571 | Y5: =L5/$L$44 -> 2681.9518 | Z5: =M5/$M$44 -> 2807.8349 | AA5: =SUM(O5:Z5) -> 31898.374 | AD5: 2321.0903 | AE5: =AD5/0.95474 -> 2431.1229 | AF5: =AE5-Z5 -> -376.71204
A6: Brett Brothers | B6: 711.78973 | C6: 642.90685 | D6: 711.78973 | E6: 688.82877 | F6: 711.78973 | G6: 688.82877 | H6: 711.78973 | I6: 711.78973 | J6: 688.82877 | K6: 711.78973 | L6: 688.82877 | M6: 711.78973 | N6: =SUM(B6:M6) -> 8380.75 | O6: =B6/$B$44 -> 736.43832 | P6: =C6/$C$44 -> 669.32511 | Q6: =D6/$D$44 -> 767.58552 | R6: =E6/$E$44 -> 773.8171 | S6: =F6/$F$44 -> 802.76735 | T6: =G6/$G$44 -> 793.51754 | U6: =H6/$H$44 -> 831.82158 | V6: =I6/$I$44 -> 829.04099 | W6: =J6/$J$44 -> 808.02924 | X6: =K6/$K$44 -> 828.79966 | Y6: =L6/$L$44 -> 796.31542 | Z6: =M6/$M$44 -> 833.6922 | AA6: =SUM(O6:Z6) -> 9471.15 | AD6: 689.16981 | AE6: =AD6/0.95474 -> 721.8403 | AF6: =AE6-Z6 -> -111.8519
A7: Callan Co-Op | B7: 495.05556 | C7: 447.14696 | D7: 495.05556 | E7: 479.08603 | F7: 495.05556 | G7: 479.08603 | H7: 495.05556 | I7: 495.05556 | J7: 479.08603 | K7: 495.05556 | L7: 479.08603 | M7: 495.05556 | N7: =SUM(B7:M7) -> 5828.88 | O7: =B7/$B$44 -> 512.19886 | P7: =C7/$C$44 -> 465.52108 | Q7: =D7/$D$44 -> 533.86199 | R7: =E7/$E$44 -> 538.19611 | S7: =F7/$F$44 -> 558.33124 | T7: =G7/$G$44 -> 551.89792 | U7: =H7/$H$44 -> 578.5387 | V7: =I7/$I$44 -> 576.60477 | W7: =J7/$J$44 -> 561.99093 | X7: =K7/$K$44 -> 576.43693 | Y7: =L7/$L$44 -> 553.84387 | Z7: =M7/$M$44 -> 579.83973 | AA7: =SUM(O7:Z7) -> 6587.2621 | AD7: 479.32352 | AE7: =AD7/0.95474 -> 502.04613 | AF7: =AE7-Z7 -> -77.793594
A8: Carbery | B8: 585.95436 | C8: 529.2491 | D8: 585.95436 | E8: 567.0526 | F8: 585.95436 | G8: 567.0526 | H8: 585.95436 | I8: 585.95436 | J8: 567.0526 | K8: 585.95436 | L8: 567.0526 | M8: 585.95436 | N8: =SUM(B8:M8) -> 6899.14 | O8: =B8/$B$44 -> 606.24539 | P8: =C8/$C$44 -> 550.99695 | Q8: =D8/$D$44 -> 631.88616 | R8: =E8/$E$44 -> 637.01608 | S8: =F8/$F$44 -> 660.84829 | T8: =G8/$G$44 -> 653.23373 | U8: =H8/$H$44 -> 684.76611 | V8: =I8/$I$44 -> 682.47709 | W8: =J8/$J$44 -> 665.17995 | X8: =K8/$K$44 -> 682.27842 | Y8: =L8/$L$44 -> 655.53698 | Z8: =M8/$M$44 -> 686.30602 | AA8: =SUM(O8:Z8) -> 7796.7712 | AD8: 567.33303 | AE8: =AD8/0.95474 -> 594.22778 | AF8: =AE8-Z8 -> -92.078241
A9: Centenary Thurles Co-Op | B9: 581.97532 | C9: 525.65512 | D9: 581.97532 | E9: 563.20192 | F9: 581.97532 | G9: 563.20192 | H9: 581.97532 | I9: 581.97532 | J9: 563.20192 | K9: 581.97532 | L9: 563.20192 | M9: 581.97532 | N9: =SUM(B9:M9) -> 6852.29 | O9: =B9/$B$44 -> 602.12856 | P9: =C9/$C$44 -> 547.25529 | Q9: =D9/$D$44 -> 627.59521 | R9: =E9/$E$44 -> 632.69029 | S9: =F9/$F$44 -> 656.36067 | T9: =G9/$G$44 -> 648.79781 | U9: =H9/$H$44 -> 680.11606 | V9: =I9/$I$44 -> 677.84259 | W9: =J9/$J$44 -> 660.66291 | X9: =K9/$K$44 -> 677.64527 | Y9: =L9/$L$44 -> 651.08543 | Z9: =M9/$M$44 -> 681.64552 | AA9: =SUM(O9:Z9) -> 7743.8256 | AD9: 563.4809 | AE9: =AD9/0.95474 -> 590.19304 | AF9: =AE9-Z9 -> -91.452485
A10: Dan O'Connor | B10: 141.28186 | C10: 127.60942 | D10: 141.28186 | E10: 136.72438 | F10: 141.28186 | G10: 136.72438 | H10: 141.28186 | I10: 141.28186 | J10: 136.72438 | K10: 141.28186 | L10: 136.72438 | M10: 141.28186 | N10: =SUM(B10:M10) -> 1663.48 | O10: =B10/$B$44 -> 146.17432 | P10: =C10/$C$44 -> 132.85314 | Q10: =D10/$D$44 -> 152.35667 | R10: =E10/$E$44 -> 153.59356 | S10: =F10/$F$44 -> 159.33985 | T10: =G10/$G$44 -> 157.50387 | U10: =H10/$H$44 -> 165.10677 | V10: =I10/$I$44 -> 164.55486 | W10: =J10/$J$44 -> 160.38427 | X10: =K10/$K$44 -> 164.50695 | Y10: =L10/$L$44 -> 158.05922 | Z10: =M10/$M$44 -> 165.47807 | AA10: =SUM(O10:Z10) -> 1879.9115 | AD10: 136.79216 | AE10: =AD10/0.95474 -> 143.27687 | AF10: =AE10-Z10 -> -22.201196
A11: Denis Brinicombe | B11: 2069.4267 | C11: 1869.1596 | D11: 2069.4267 | E11: 2002.671 | F11: 2069.4267 | G11: 2002.671 | H11: -679.48732 | I11: 1667.4628 | J11: 1613.6737 | K11: 1667.4628 | L11: 1613.6737 | M11: 1667.4628 | N11: =SUM(B11:M11) -> 19633.03 | O11: =B11/$B$44 -> 2141.0889 | P11: =C11/$C$44 -> 1945.9669 | Q11: =D11/$D$44 -> 2231.6449 | R11: =E11/$E$44 -> 2249.7624 | S11: =F11/$F$44 -> 2333.9311 | T11: =G11/$G$44 -> 2307.0386 | U11: =H11/$H$44 -> -794.07189 | V11: =I11/$I$44 -> 1942.1396 | W11: =J11/$J$44 -> 1892.9168 | X11: =K11/$K$44 -> 1941.5743 | Y11: =L11/$L$44 -> 1865.4756 | Z11: =M11/$M$44 -> 1953.0357 | AA11: =SUM(O11:Z11) -> 22010.503 | AD11: 1914.1238 | AE11: =AD11/0.95474 -> 2004.8639 | AF11: =AE11-Z11 -> 51.828237
A12: Drinagh Co-Op | B12: 2206.2819 | C12: 1992.7707 | D12: 2206.2819 | E12: 2135.1115 | F12: 2206.2819 | G12: 2135.1115 | H12: 2206.2819 | I12: 2206.2819 | J12: 2135.1115 | K12: 2206.2819 | L12: 2135.1115 | M12: 2206.2819 | N12: =SUM(B12:M12) -> 25977.19 | O12: =B12/$B$44 -> 2282.6833 | P12: =C12/$C$44 -> 2074.6575 | Q12: =D12/$D$44 -> 2379.228 | R12: =E12/$E$44 -> 2398.5435 | S12: =F12/$F$44 -> 2488.2785 | T12: =G12/$G$44 -> 2459.6075 | U12: =H12/$H$44 -> 2578.3357 | V12: =I12/$I$44 -> 2569.717 | W12: =J12/$J$44 -> 2504.5884 | X12: =K12/$K$44 -> 2568.9689 | Y12: =L12/$L$44 -> 2468.2799 | Z12: =M12/$M$44 -> 2584.134 | AA12: =SUM(O12:Z12) -> 29357.022 | AD12: 135.43781 | AE12: =AD12/0.95474 -> 141.85832 | AF12: =AE12-Z12 -> -2442.2756
A13: Drinagh Dairies | B13: 139.88304 | C13: 126.34597 | D13: 139.88304 | E13: 135.37068 | F13: 139.88304 | G13: 135.37068 | H13: 139.88304 | I13: 139.88304 | J13: 135.37068 | K13: 139.88304 | L13: 135.37068 | M13: 139.88304 | N13: =SUM(B13:M13) -> 1647.01 | O13: =B13/$B$44 -> 144.72706 | P13: =C13/$C$44 -> 131.53777 | Q13: =D13/$D$44 -> 150.8482 | R13: =E13/$E$44 -> 152.07285 | S13: =F13/$F$44 -> 157.76224 | T13: =G13/$G$44 -> 155.94443 | U13: =H13/$H$44 -> 163.47206 | V13: =I13/$I$44 -> 162.92561 | W13: =J13/$J$44 -> 158.79632 | X13: =K13/$K$44 -> 162.87818 | Y13: =L13/$L$44 -> 156.49428 | Z13: =M13/$M$44 -> 163.83968 | AA13: =SUM(O13:Z13) -> 1861.2987 | AD13: 10704.238 | AE13: =AD13/0.95474 -> 11211.679 | AF13: =AE13-Z13 -> 11047.839
... A15: Hopkins | B15: 585.95436 | C15: 529.2491 | D15: 585.95436 | E15: 567.0526 | F15: 585.95436 | G15: 567.0526 | H15: 585.95436 | I15: 585.95436 | J15: 567.0526 | K15: 585.95436 | L15: 567.0526 | M15: 585.95436 | N15: =SUM(B15:M15) -> 6899.14 | O15: =B15/$B$44 -> 606.24539 | P15: =C15/$C$44 -> 550.99695 | Q15: =D15/$D$44 -> 631.88616 | R15: =E15/$E$44 -> 637.01608 | S15: =F15/$F$44 -> 660.84829 | T15: =G15/$G$44 -> 653.23373 | U15: =H15/$H$44 -> 684.76611 | V15: =I15/$I$44 -> 682.47709 | W15: =J15/$J$44 -> 665.17995 | X15: =K15/$K$44 -> 682.27842 | Y15: =L15/$L$44 -> 655.53698 | Z15: =M15/$M$44 -> 686.30602 | AA15: =SUM(O15:Z15) -> 7796.7712 | AD15: 600.7512 | AE15: =AD15/0.95474 -> 629.23016 | AF15: =AE15-Z15 -> -57.075864
A16: ICMSA | B16: 735.52723 | C16: 664.34718 | D16: 735.52723 | E16: 711.80055 | F16: 735.52723 | G16: 711.80055 | H16: 735.52723 | I16: 735.52723 | J16: 711.80055 | K16: 735.52723 | L16: 711.80055 | M16: 735.52723 | N16: =SUM(B16:M16) -> 8660.24 | O16: =B16/$B$44 -> 760.99783 | P16: =C16/$C$44 -> 691.64646 | Q16: =D16/$D$44 -> 793.18376 | R16: =E16/$E$44 -> 799.62316 | S16: =F16/$F$44 -> 829.53887 | T16: =G16/$G$44 -> 819.98059 | U16: =H16/$H$44 -> 859.56203 | V16: =I16/$I$44 -> 856.68872 | W16: =J16/$J$44 -> 834.97624 | X16: =K16/$K$44 -> 856.43934 | Y16: =L16/$L$44 -> 822.87178 | Z16: =M16/$M$44 -> 861.49504 | AA16: =SUM(O16:Z16) -> 9787.0038
A17: J.McKenna | B17: 620.46882 | C17: 560.42345 | D17: 620.46882 | E17: 600.4537 | F17: 620.46882 | G17: 600.4537 | H17: 620.46882 | I17: 620.46882 | J17: 600.4537 | K17: 620.46882 | L17: 600.4537 | M17: 620.46882 | N17: =SUM(B17:M17) -> 7305.52 | O17: =B17/$B$44 -> 641.95506 | P17: =C17/$C$44 -> 583.45231 | Q17: =D17/$D$44 -> 669.10615 | R17: =E17/$E$44 -> 674.53823 | S17: =F17/$F$44 -> 699.77424 | T17: =G17/$G$44 -> 691.71115 | U17: =H17/$H$44 -> 725.10088 | V17: =I17/$I$44 -> 722.67703 | W17: =J17/$J$44 -> 704.36104 | X17: =K17/$K$44 -> 722.46667 | Y17: =L17/$L$44 -> 694.15008 | Z17: =M17/$M$44 -> 726.7315 | AA17: =SUM(O17:Z17) -> 8256.0243
